Workbook

Sheet Home
C1: Total Deu Summary
I2: Total Cedit
B3: Market | C3: Name | D3: Last Collection | E3: Deu
B4: Bhandaria | C4: =HYPERLINK("#'Moumita'!A1", "Moumita") -> Moumita | D4: {=LOOKUP(2, 1/(Moumita!D4:D500<>""), Moumita!D4:D500)} -> 20000 | E4: {=LOOKUP(2, 1/(Moumita!E4:E500<>""), Moumita!E4:E500)} -> 231438
B5: Bhandaria | C5: =HYPERLINK("#'Razapur'!A1", "Razapur") -> Razapur | D5: {=LOOKUP(2, 1/(Razapur!D4:D500<>""), Razapur!D4:D500)} -> 2000 | E5: {=LOOKUP(2, 1/(Razapur!E4:E500<>""), Razapur!E4:E500)} -> 24878 | I5: =SUM(E4:E1048576) -> 764326
B6: Bhandaria | C6: =HYPERLINK("#'Kabir'!A1", "Kabir") -> Kabir | D6: {=LOOKUP(2, 1/(Kabir!D4:D500<>""), Kabir!D4:D500)} -> 2000 | E6: {=LOOKUP(2, 1/(Kabir!E4:E500<>""), Kabir!E4:E500)} -> 22116
B7: Bhandaria | C7: =HYPERLINK("#'Miya'!A1", "Miya") -> Miya | D7: {=LOOKUP(2, 1/(Miya!D4:D500<>""), Miya!D4:D500)} -> 2000 | E7: {=LOOKUP(2, 1/(Miya!E4:E500<>""), Miya!E4:E500)} -> 25574
B8: Bhandaria | C8: =HYPERLINK("#'Rafid'!A1", "Rafid") -> Rafid | D8: {=LOOKUP(2, 1/(Rafid!D4:D500<>""), Rafid!D4:D500)} -> 3000 | E8: {=LOOKUP(2, 1/(Rafid!E4:E500<>""), Rafid!E4:E500)} -> 16000
B9: Bhandaria | C9: =HYPERLINK("#'Fatema'!A1", "Fatema") -> Fatema | D9: {=LOOKUP(2, 1/(Fatema!D4:D500<>""), Fatema!D4:D500)} -> 50000 | E9: {=LOOKUP(2, 1/(Fatema!E4:E500<>""), Fatema!E4:E500)} -> 44719
B10: Bhandaria | C10: =HYPERLINK("#'Badhon'!A1", "Badhon") -> Badhon | D10: {=LOOKUP(2, 1/(Badhon!D4:D500<>""), Badhon!D4:D500)} -> 45800 | E10: {=LOOKUP(2, 1/(Badhon!E4:E500<>""), Badhon!E4:E500)} -> 0 | I10: Market | J10: Outlate | K10: Market wise Deu
B11: Bhandaria | C11: =HYPERLINK("#'Alam'!A1", "Alam") -> Alam | D11: =LOOKUP(2, 1/(Alam!D4:D500<>""), Alam!D4:D500) -> 1000 | E11: =LOOKUP(2, 1/(Alam!E4:E500<>""), Alam!E4:E500) -> 4732 | I11: Bhandaria | J11: 8 | K11: 469635
B12: Mathbaria | C12: =HYPERLINK("#'PakAzad'!A1", "PakAzad") -> PakAzad | D12: =LOOKUP(2, 1/(PakAzad!D4:D500<>""), PakAzad!D4:D500) -> 7000 | E12: =LOOKUP(2, 1/(PakAzad!E4:E500<>""), PakAzad!E4:E500) -> 47616 | I12: Mathbaria | J12: 6 | K12: 270571
B13: Mathbaria | C13: =HYPERLINK("#'Himel'!A1", "Himel") -> Himel | D13: =LOOKUP(2, 1/(Himel!D4:D500<>""), Himel!D4:D500) -> 5000 | E13: =LOOKUP(2, 1/(Himel!E4:E500<>""), Himel!E4:E500) -> 1022 | I13: Zianagar | J13: 8 | K13: 183024
B14: Mathbaria | C14: =HYPERLINK("#'BhaiBhai'!A1", "BhaiBhai") -> BhaiBhai | D14: =LOOKUP(2, 1/(BhaiBhai!D4:D500<>""), BhaiBhai!D4:D500) -> 3000 | E14: =LOOKUP(2, 1/(BhaiBhai!E4:E500<>""), BhaiBhai!E4:E500) -> 3450 | I14: Grand Total | J14: 22 | K14: 923230
B15: Mathbaria | C15: =HYPERLINK("#'Akon'!A1", "Akon") -> Akon | D15: =LOOKUP(2, 1/(Akon!D4:D500<>""), Akon!D4:D500) -> 5000 | E15: =LOOKUP(2, 1/(Akon!E4:E500<>""), Akon!E4:E500) -> 15000
B16: Mathbaria | C16: =HYPERLINK("#'Modina'!A1", "Modina") -> Modina | D16: =LOOKUP(2, 1/(Modina!D4:D500<>""), Modina!D4:D500) -> 10000 | E16: =LOOKUP(2, 1/(Modina!E4:E500<>""), Modina!E4:E500) -> 90945
B17: Mathbaria | C17: =HYPERLINK("#'Digital'!A1", "Digital") -> Digital | D17: =LOOKUP(2, 1/(Digital!D4:D500<>""), Digital!D4:D500) -> 8000 | E17: =LOOKUP(2, 1/(Digital!E4:E500<>""), Digital!E4:E500) -> 52538
B18: Zianagar | C18: =HYPERLINK("#'Talukder'!A1", "Talukder") -> Talukder | D18: =LOOKUP(2, 1/(Talukder!D4:D500<>""), Talukder!D4:D500) -> 2000 | E18: =LOOKUP(2, 1/(Talukder!E4:E500<>""), Talukder!E4:E500) -> 5500
B19: Zianagar | C19: =HYPERLINK("#'Khan'!A1", "Khan") -> Khan | D19: =LOOKUP(2, 1/(Khan!D4:D500<>""), Khan!D4:D500) -> 1000 | E19: =LOOKUP(2, 1/(Khan!E4:E500<>""), Khan!E4:E500) -> 5395
B20: Zianagar | C20: =HYPERLINK("#'Naim'!A1", "Naim") -> Naim | D20: =LOOKUP(2, 1/(Naim!D4:D500<>""), Naim!D4:D500) -> 1400 | E20: =LOOKUP(2, 1/(Naim!E4:E500<>""), Naim!E4:E500) -> 10400
B21: Zianagar | C21: =HYPERLINK("#'Hasan'!A1", "Hasan") -> Hasan | D21: =LOOKUP(2, 1/(Hasan!D4:D500<>""), Hasan!D4:D500) -> 2000 | E21: =LOOKUP(2, 1/(Hasan!E4:E500<>""), Hasan!E4:E500) -> 3600
B22: Zianagar | C22: =HYPERLINK("#'RafiqZ'!A1", "RafiqZ") -> RafiqZ | D22: =LOOKUP(2, 1/(RafiqZ!D4:D500<>""), RafiqZ!D4:D500) -> 530 | E22: =LOOKUP(2, 1/(RafiqZ!E4:E500<>""), RafiqZ!E4:E500) -> 3274
B23: Zianagar | C23: =HYPERLINK("#'Ebrahim'!A1", "Ebrahim") -> Ebrahim | D23: =LOOKUP(2, 1/(Ebrahim!D4:D500<>""), Ebrahim!D4:D500) -> 1040 | E23: =LOOKUP(2, 1/(Ebrahim!E4:E500<>""), Ebrahim!E4:E500) -> 0
B24: Zianagar | C24: =HYPERLINK("#'RafiqB'!A1", "RafiqB") -> RafiqB | D24: =LOOKUP(2, 1/(RafiqB!D4:D500<>""), RafiqB!D4:D500) -> 2000 | E24: =LOOKUP(2, 1/(RafiqB!E4:E500<>""), RafiqB!E4:E500) -> 14360
B25: Zianagar | C25: =HYPERLINK("#'Maisha'!A1", "Maisha") -> Maisha | D25: =LOOKUP(2, 1/(Maisha!D4:D500<>""), Maisha!D4:D500) -> 5000 | E25: =LOOKUP(2, 1/(Maisha!E4:E500<>""), Maisha!E4:E500) -> 141769

Sheet Moumita
A1: =HYPERLINK("#'Home'!A1", "Home") -> Home | B1: Moumita Electonics
A3: Date | B3: Product | C3: Total | D3: Deposite | E3: Deu
A4: 45914 | B4: 71599 | C4: =IF(B4="", "", SUM($B$4:B4)) -> 71599 | E4: =IF(AND(B4="", D4=""), "", N(LOOKUP(2, 1/($E$3:E3<>""), $E$3:E3)) + B4 - D4) -> 71599
A5: 45924 | B5: 104760 | C5: =IF(B5="", "", SUM($B$4:B5)) -> 176359 | E5: =IF(AND(B5="", D5=""), "", N(LOOKUP(2, 1/($E$3:E4<>""), $E$3:E4)) + B5 - D5) -> 176359
C6: =IF(B6="", "", SUM($B$4:B6)) | D6: 3400 | E6: =IF(AND(B6="", D6=""), "", N(LOOKUP(2, 1/($E$3:E5<>""), $E$3:E5)) + B6 - D6) -> 172959 | F6: Fatema Induction-1P
A7: 45905 | B7: 3812 | C7: =IF(B7="", "", SUM($B$4:B7)) -> 180171 | E7: =IF(AND(B7="", D7=""), "", N(LOOKUP(2, 1/($E$3:E6<>""), $E$3:E6)) + B7 - D7) -> 176771
A8: 45973 | C8: =IF(B8="", "", SUM($B$4:B8)) | D8: 20000 | E8: =IF(AND(B8="", D8=""), "", N(LOOKUP(2, 1/($E$3:E7<>""), $E$3:E7)) + B8 - D8) -> 156771
A9: 45977 | C9: =IF(B9="", "", SUM($B$4:B9)) | D9: 30000 | E9: =IF(AND(B9="", D9=""), "", N(LOOKUP(2, 1/($E$3:E8<>""), $E$3:E8)) + B9 - D9) -> 126771
A10: 45995 | B10: 76289 | C10: =IF(B10="", "", SUM($B$4:B10)) -> 256460 | E10: =IF(AND(B10="", D10=""), "", N(LOOKUP(2, 1/($E$3:E9<>""), $E$3:E9)) + B10 - D10) -> 203060
C11: =IF(B11="", "", SUM($B$4:B11)) | D11: 400 | E11: =IF(AND(B11="", D11=""), "", N(LOOKUP(2, 1/($E$3:E10<>""), $E$3:E10)) + B11 - D11) -> 202660 | F11: 05.11.25 SS plate Adjust-400/-
A12: 46005 | C12: =IF(B12="", "", SUM($B$4:B12)) | D12: 20000 | E12: =IF(AND(B12="", D12=""), "", N(LOOKUP(2, 1/($E$3:E11<>""), $E$3:E11)) + B12 - D12) -> 182660
A13: 46008 | C13: =IF(B13="", "", SUM($B$4:B13)) | D13: =10000+10000 -> 20000 | E13: =IF(AND(B13="", D13=""), "", N(LOOKUP(2, 1/($E$3:E12<>""), $E$3:E12)) + B13 - D13) -> 162660
A14: 46018 | B14: 97188 | C14: =IF(B14="", "", SUM($B$4:B14)) -> 353648 | E14: =IF(AND(B14="", D14=""), "", N(LOOKUP(2, 1/($E$3:E13<>""), $E$3:E13)) + B14 - D14) -> 259848
A15: 46037 | C15: =IF(B15="", "", SUM($B$4:B15)) | D15: 20000 | E15: =IF(AND(B15="", D15=""), "", N(LOOKUP(2, 1/($E$3:E14<>""), $E$3:E14)) + B15 - D15) -> 239848
A16: 46047 | C16: =IF(B16="", "", SUM($B$4:B16)) | D16: 70000 | E16: =IF(AND(B16="", D16=""), "", N(LOOKUP(2, 1/($E$3:E15<>""), $E$3:E15)) + B16 - D16) -> 169848
A17: 46049 | B17: 136085 | C17: =IF(B17="", "", SUM($B$4:B17)) -> 489733 | E17: =IF(AND(B17="", D17=""), "", N(LOOKUP(2, 1/($E$3:E16<>""), $E$3:E16)) + B17 - D17) -> 305933
A18: 46068 | C18: =IF(B18="", "", SUM($B$4:B18)) | D18: 20000 | E18: =IF(AND(B18="", D18=""), "", N(LOOKUP(2, 1/($E$3:E17<>""), $E$3:E17)) + B18 - D18) -> 285933
A19: 46091 | C19: =IF(B19="", "", SUM($B$4:B19)) | D19: 40000 | E19: =IF(AND(B19="", D19=""), "", N(LOOKUP(2, 1/($E$3:E18<>""), $E$3:E18)) + B19 - D19) -> 245933
A20: 46114 | B20: 10716 | C20: =IF(B20="", "", SUM($B$4:B20)) -> 500449 | E20: =IF(AND(B20="", D20=""), "", N(LOOKUP(2, 1/($E$3:E19<>""), $E$3:E19)) + B20 - D20) -> 256649
A21: 46120 | B21: 7896 | C21: =IF(B21="", "", SUM($B$4:B21)) -> 508345 | E21: =IF(AND(B21="", D21=""), "", N(LOOKUP(2, 1/($E$3:E20<>""), $E$3:E20)) + B21 - D21) -> 264545
A22: 46120 | C22: =IF(B22="", "", SUM($B$4:B22)) | D22: 10000 | E22: =IF(AND(B22="", D22=""), "", N(LOOKUP(2, 1/($E$3:E21<>""), $E$3:E21)) + B22 - D22) -> 254545
A23: 46127 | C23: =IF(B23="", "", SUM($B$4:B23)) | D23: 50000 | E23: =IF(AND(B23="", D23=""), "", N(LOOKUP(2, 1/($E$3:E22<>""), $E$3:E22)) + B23 - D23) -> 204545
A24: 46135 | B24: 96893 | C24: =IF(B24="", "", SUM($B$4:B24)) -> 605238 | E24: =IF(AND(B24="", D24=""), "", N(LOOKUP(2, 1/($E$3:E23<>""), $E$3:E23)) + B24 - D24) -> 301438
A25: 46155 | C25: =IF(B25="", "", SUM($B$4:B25)) | D25: 30000 | E25: =IF(AND(B25="", D25=""), "", N(LOOKUP(2, 1/($E$3:E24<>""), $E$3:E24)) + B25 - D25) -> 271438
A26: 46183 | C26: =IF(B26="", "", SUM($B$4:B26)) | D26: 20000 | E26: =IF(AND(B26="", D26=""), "", N(LOOKUP(2, 1/($E$3:E25<>""), $E$3:E25)) + B26 - D26) -> 251438
A27: 46187 | C27: =IF(B27="", "", SUM($B$4:B27)) | D27: 20000 | E27: =IF(AND(B27="", D27=""), "", N(LOOKUP(2, 1/($E$3:E26<>""), $E$3:E26)) + B27 - D27) -> 231438
C28: =IF(B28="", "", SUM($B$4:B28)) | E28: =IF(AND(B28="", D28=""), "", N(LOOKUP(2, 1/($E$3:E27<>""), $E$3:E27)) + B28 - D28)
C29: =IF(B29="", "", SUM($B$4:B29)) | E29: =IF(AND(B29="", D29=""), "", N(LOOKUP(2, 1/($E$3:E28<>""), $E$3:E28)) + B29 - D29)
C30: =IF(B30="", "", SUM($B$4:B30)) | E30: =IF(AND(B30="", D30=""), "", N(LOOKUP(2, 1/($E$3:E29<>""), $E$3:E29)) + B30 - D30)
C31: =IF(B31="", "", SUM($B$4:B31)) | E31: =IF(AND(B31="", D31=""), "", N(LOOKUP(2, 1/($E$3:E30<>""), $E$3:E30)) + B31 - D31)
C32: =IF(B32="", "", SUM($B$4:B32)) | E32: =IF(AND(B32="", D32=""), "", N(LOOKUP(2, 1/($E$3:E31<>""), $E$3:E31)) + B32 - D32)
C33: =IF(B33="", "", SUM($B$4:B33)) | E33: =IF(AND(B33="", D33=""), "", N(LOOKUP(2, 1/($E$3:E32<>""), $E$3:E32)) + B33 - D33)
C34: =IF(B34="", "", SUM($B$4:B34)) | E34: =IF(AND(B34="", D34=""), "", N(LOOKUP(2, 1/($E$3:E33<>""), $E$3:E33)) + B34 - D34)
C35: =IF(B35="", "", SUM($B$4:B35)) | E35: =IF(AND(B35="", D35=""), "", N(LOOKUP(2, 1/($E$3:E34<>""), $E$3:E34)) + B35 - D35)
C36: =IF(B36="", "", SUM($B$4:B36)) | E36: =IF(AND(B36="", D36=""), "", N(LOOKUP(2, 1/($E$3:E35<>""), $E$3:E35)) + B36 - D36)
C37: =IF(B37="", "", SUM($B$4:B37)) | E37: =IF(AND(B37="", D37=""), "", N(LOOKUP(2, 1/($E$3:E36<>""), $E$3:E36)) + B37 - D37)
C38: =IF(B38="", "", SUM($B$4:B38)) | E38: =IF(AND(B38="", D38=""), "", N(LOOKUP(2, 1/($E$3:E37<>""), $E$3:E37)) + B38 - D38)
C39: =IF(B39="", "", SUM($B$4:B39)) | E39: =IF(AND(B39="", D39=""), "", N(LOOKUP(2, 1/($E$3:E38<>""), $E$3:E38)) + B39 - D39)
... C100: =IF(B100="", "", SUM($B$4:B100)) | E100: =IF(AND(B100="", D100=""), "", N(LOOKUP(2, 1/($E$3:E99<>""), $E$3:E99)) + B100 - D100)
C101: =IF(B101="", "", SUM($B$4:B101)) | E101: =IF(AND(B101="", D101=""), "", SUM($B$4:B101) - SUM($D$4:D101))
...

Sheet Razapur
A1: =HYPERLINK("#'Home'!A1", "Home") -> Home | B1: Razapur Crockery
A3: Date | B3: Product | C3: Total | D3: Deposite | E3: Deu
A4: 45910 | B4: 20076 | C4: =IF(B4="", "", SUM($B$4:B4)) -> 20076 | E4: =IF(AND(B4="", D4=""), "", N(LOOKUP(2, 1/($E$3:E3<>""), $E$3:E3)) + B4 - D4) -> 20076
A5: 45917 | C5: =IF(B5="", "", SUM($B$4:B5)) | D5: 20000 | E5: =IF(AND(B5="", D5=""), "", N(LOOKUP(2, 1/($E$3:E4<>""), $E$3:E4)) + B5 - D5) -> 76
A6: 45924 | B6: 33222 | C6: =IF(B6="", "", SUM($B$4:B6)) -> 53298 | E6: =IF(AND(B6="", D6=""), "", N(LOOKUP(2, 1/($E$3:E5<>""), $E$3:E5)) + B6 - D6) -> 33298
A7: 45931 | C7: =IF(B7="", "", SUM($B$4:B7)) | D7: 5000 | E7: =IF(AND(B7="", D7=""), "", N(LOOKUP(2, 1/($E$3:E6<>""), $E$3:E6)) + B7 - D7) -> 28298
A8: 45938 | C8: =IF(B8="", "", SUM($B$4:B8)) | D8: 3000 | E8: =IF(AND(B8="", D8=""), "", N(LOOKUP(2, 1/($E$3:E7<>""), $E$3:E7)) + B8 - D8) -> 25298
A9: 45945 | C9: =IF(B9="", "", SUM($B$4:B9)) | D9: 4000 | E9: =IF(AND(B9="", D9=""), "", N(LOOKUP(2, 1/($E$3:E8<>""), $E$3:E8)) + B9 - D9) -> 21298
A10: 45952 | C10: =IF(B10="", "", SUM($B$4:B10)) | D10: 4000 | E10: =IF(AND(B10="", D10=""), "", N(LOOKUP(2, 1/($E$3:E9<>""), $E$3:E9)) + B10 - D10) -> 17298
A11: 45959 | C11: =IF(B11="", "", SUM($B$4:B11)) | D11: 2000 | E11: =IF(AND(B11="", D11=""), "", N(LOOKUP(2, 1/($E$3:E10<>""), $E$3:E10)) + B11 - D11) -> 15298
A12: 45966 | B12: 4800 | C12: =IF(B12="", "", SUM($B$4:B12)) -> 58098 | E12: =IF(AND(B12="", D12=""), "", N(LOOKUP(2, 1/($E$3:E11<>""), $E$3:E11)) + B12 - D12) -> 20098
A13: 45966 | C13: =IF(B13="", "", SUM($B$4:B13)) | D13: 4000 | E13: =IF(AND(B13="", D13=""), "", N(LOOKUP(2, 1/($E$3:E12<>""), $E$3:E12)) + B13 - D13) -> 16098
A14: 45973 | C14: =IF(B14="", "", SUM($B$4:B14)) | D14: 3000 | E14: =IF(AND(B14="", D14=""), "", N(LOOKUP(2, 1/($E$3:E13<>""), $E$3:E13)) + B14 - D14) -> 13098
A15: 45980 | C15: =IF(B15="", "", SUM($B$4:B15)) | D15: 2000 | E15: =IF(AND(B15="", D15=""), "", N(LOOKUP(2, 1/($E$3:E14<>""), $E$3:E14)) + B15 - D15) -> 11098
A16: 45985 | B16: 4800 | C16: =IF(B16="", "", SUM($B$4:B16)) -> 62898 | E16: =IF(AND(B16="", D16=""), "", N(LOOKUP(2, 1/($E$3:E15<>""), $E$3:E15)) + B16 - D16) -> 15898
A17: 45987 | C17: =IF(B17="", "", SUM($B$4:B17)) | D17: 2000 | E17: =IF(AND(B17="", D17=""), "", N(LOOKUP(2, 1/($E$3:E16<>""), $E$3:E16)) + B17 - D17) -> 13898
A18: 45994 | C18: =IF(B18="", "", SUM($B$4:B18)) | D18: 1000 | E18: =IF(AND(B18="", D18=""), "", N(LOOKUP(2, 1/($E$3:E17<>""), $E$3:E17)) + B18 - D18) -> 12898
A19: 45995 | B19: 18240 | C19: =IF(B19="", "", SUM($B$4:B19)) -> 81138 | E19: =IF(AND(B19="", D19=""), "", N(LOOKUP(2, 1/($E$3:E18<>""), $E$3:E18)) + B19 - D19) -> 31138
A20: 46001 | C20: =IF(B20="", "", SUM($B$4:B20)) | D20: 3000 | E20: =IF(AND(B20="", D20=""), "", N(LOOKUP(2, 1/($E$3:E19<>""), $E$3:E19)) + B20 - D20) -> 28138
A21: 46008 | C21: =IF(B21="", "", SUM($B$4:B21)) | D21: 3000 | E21: =IF(AND(B21="", D21=""), "", N(LOOKUP(2, 1/($E$3:E20<>""), $E$3:E20)) + B21 - D21) -> 25138
A22: 46015 | C22: =IF(B22="", "", SUM($B$4:B22)) | D22: 3000 | E22: =IF(AND(B22="", D22=""), "", N(LOOKUP(2, 1/($E$3:E21<>""), $E$3:E21)) + B22 - D22) -> 22138
A23: 46022 | C23: =IF(B23="", "", SUM($B$4:B23)) | D23: 2000 | E23: =IF(AND(B23="", D23=""), "", N(LOOKUP(2, 1/($E$3:E22<>""), $E$3:E22)) + B23 - D23) -> 20138
A24: 46026 | B24: 20100 | C24: =IF(B24="", "", SUM($B$4:B24)) -> 101238 | E24: =IF(AND(B24="", D24=""), "", N(LOOKUP(2, 1/($E$3:E23<>""), $E$3:E23)) + B24 - D24) -> 40238
A25: 46029 | C25: =IF(B25="", "", SUM($B$4:B25)) | D25: 8076 | E25: =IF(AND(B25="", D25=""), "", N(LOOKUP(2, 1/($E$3:E24<>""), $E$3:E24)) + B25 - D25) -> 32162 | F25: 17.09.25 Adjust-76/-
A26: 46036 | C26: =IF(B26="", "", SUM($B$4:B26)) | D26: 4000 | E26: =IF(AND(B26="", D26=""), "", N(LOOKUP(2, 1/($E$3:E25<>""), $E$3:E25)) + B26 - D26) -> 28162
A27: 46043 | C27: =IF(B27="", "", SUM($B$4:B27)) | D27: 3000 | E27: =IF(AND(B27="", D27=""), "", N(LOOKUP(2, 1/($E$3:E26<>""), $E$3:E26)) + B27 - D27) -> 25162
A28: 46050 | C28: =IF(B28="", "", SUM($B$4:B28)) | D28: 3000 | E28: =IF(AND(B28="", D28=""), "", N(LOOKUP(2, 1/($E$3:E27<>""), $E$3:E27)) + B28 - D28) -> 22162
A29: 46057 | C29: =IF(B29="", "", SUM($B$4:B29)) | D29: 2000 | E29: =IF(AND(B29="", D29=""), "", N(LOOKUP(2, 1/($E$3:E28<>""), $E$3:E28)) + B29 - D29) -> 20162
A30: 46071 | C30: =IF(B30="", "", SUM($B$4:B30)) | D30: 2000 | E30: =IF(AND(B30="", D30=""), "", N(LOOKUP(2, 1/($E$3:E29<>""), $E$3:E29)) + B30 - D30) -> 18162
A31: 46092 | C31: =IF(B31="", "", SUM($B$4:B31)) | D31: 3000 | E31: =IF(AND(B31="", D31=""), "", N(LOOKUP(2, 1/($E$3:E30<>""), $E$3:E30)) + B31 - D31) -> 15162
A32: 46093 | B32: 17355 | C32: =IF(B32="", "", SUM($B$4:B32)) -> 118593 | E32: =IF(AND(B32="", D32=""), "", N(LOOKUP(2, 1/($E$3:E31<>""), $E$3:E31)) + B32 - D32) -> 32517
A33: 46106 | C33: =IF(B33="", "", SUM($B$4:B33)) | D33: 10000 | E33: =IF(AND(B33="", D33=""), "", N(LOOKUP(2, 1/($E$3:E32<>""), $E$3:E32)) + B33 - D33) -> 22517
A34: 46107 | B34: 37121 | C34: =IF(B34="", "", SUM($B$4:B34)) -> 155714 | E34: =IF(AND(B34="", D34=""), "", N(LOOKUP(2, 1/($E$3:E33<>""), $E$3:E33)) + B34 - D34) -> 59638
A35: 46107 | C35: =IF(B35="", "", SUM($B$4:B35)) | D35: 3000 | E35: =IF(AND(B35="", D35=""), "", N(LOOKUP(2, 1/($E$3:E34<>""), $E$3:E34)) + B35 - D35) -> 56638
A36: 46113 | C36: =IF(B36="", "", SUM($B$4:B36)) | D36: 6000 | E36: =IF(AND(B36="", D36=""), "", N(LOOKUP(2, 1/($E$3:E35<>""), $E$3:E35)) + B36 - D36) -> 50638
A37: 46120 | C37: =IF(B37="", "", SUM($B$4:B37)) | D37: 5000 | E37: =IF(AND(B37="", D37=""), "", N(LOOKUP(2, 1/($E$3:E36<>""), $E$3:E36)) + B37 - D37) -> 45638
A38: 46127 | C38: =IF(B38="", "", SUM($B$4:B38)) | D38: 5000 | E38: =IF(AND(B38="", D38=""), "", N(LOOKUP(2, 1/($E$3:E37<>""), $E$3:E37)) + B38 - D38) -> 40638
A39: 46134 | C39: =IF(B39="", "", SUM($B$4:B39)) | D39: 3000 | E39: =IF(AND(B39="", D39=""), "", N(LOOKUP(2, 1/($E$3:E38<>""), $E$3:E38)) + B39 - D39) -> 37638
A40: 46135 | B40: 9240 | C40: =IF(B40="", "", SUM($B$4:B40)) -> 164954 | E40: =IF(AND(B40="", D40=""), "", N(LOOKUP(2, 1/($E$3:E39<>""), $E$3:E39)) + B40 - D40) -> 46878
A41: 46148 | C41: =IF(B41="", "", SUM($B$4:B41)) | D41: 5000 | E41: =IF(AND(B41="", D41=""), "", N(LOOKUP(2, 1/($E$3:E40<>""), $E$3:E40)) + B41 - D41) -> 41878
...

Sheet Kabir
A1: =HYPERLINK("#'Home'!A1", "Home") -> Home | B1: Kabir Enterprise
A3: Date | B3: Product | C3: Total | D3: Deposite | E3: Deu
A4: 45910 | B4: 7282 | C4: =IF(B4="", "", SUM($B$4:B4)) -> 7282 | E4: =IF(AND(B4="", D4=""), "", N(LOOKUP(2, 1/($E$3:E3<>""), $E$3:E3)) + B4 - D4) -> 7282
A5: 45931 | C5: =IF(B5="", "", SUM($B$4:B5)) | D5: 2000 | E5: =IF(AND(B5="", D5=""), "", N(LOOKUP(2, 1/($E$3:E4<>""), $E$3:E4)) + B5 - D5) -> 5282
A6: 45945 | C6: =IF(B6="", "", SUM($B$4:B6)) | D6: 2000 | E6: =IF(AND(B6="", D6=""), "", N(LOOKUP(2, 1/($E$3:E5<>""), $E$3:E5)) + B6 - D6) -> 3282
A7: 45957 | B7: 9600 | C7: =IF(B7="", "", SUM($B$4:B7)) -> 16882 | E7: =IF(AND(B7="", D7=""), "", N(LOOKUP(2, 1/($E$3:E6<>""), $E$3:E6)) + B7 - D7) -> 12882
A8: 45959 | C8: =IF(B8="", "", SUM($B$4:B8)) | D8: 2000 | E8: =IF(AND(B8="", D8=""), "", N(LOOKUP(2, 1/($E$3:E7<>""), $E$3:E7)) + B8 - D8) -> 10882
A9: 45966 | C9: =IF(B9="", "", SUM($B$4:B9)) | D9: 1000 | E9: =IF(AND(B9="", D9=""), "", N(LOOKUP(2, 1/($E$3:E8<>""), $E$3:E8)) + B9 - D9) -> 9882
A10: 45973 | C10: =IF(B10="", "", SUM($B$4:B10)) | D10: 1000 | E10: =IF(AND(B10="", D10=""), "", N(LOOKUP(2, 1/($E$3:E9<>""), $E$3:E9)) + B10 - D10) -> 8882
A11: 45987 | C11: =IF(B11="", "", SUM($B$4:B11)) | D11: 1000 | E11: =IF(AND(B11="", D11=""), "", N(LOOKUP(2, 1/($E$3:E10<>""), $E$3:E10)) + B11 - D11) -> 7882
A12: 46001 | C12: =IF(B12="", "", SUM($B$4:B12)) | D12: 1000 | E12: =IF(AND(B12="", D12=""), "", N(LOOKUP(2, 1/($E$3:E11<>""), $E$3:E11)) + B12 - D12) -> 6882
A13: 46029 | C13: =IF(B13="", "", SUM($B$4:B13)) | D13: 1000 | E13: =IF(AND(B13="", D13=""), "", N(LOOKUP(2, 1/($E$3:E12<>""), $E$3:E12)) + B13 - D13) -> 5882
A14: 46043 | C14: =IF(B14="", "", SUM($B$4:B14)) | D14: 1000 | E14: =IF(AND(B14="", D14=""), "", N(LOOKUP(2, 1/($E$3:E13<>""), $E$3:E13)) + B14 - D14) -> 4882
A15: 46050 | C15: =IF(B15="", "", SUM($B$4:B15)) | D15: 1000 | E15: =IF(AND(B15="", D15=""), "", N(LOOKUP(2, 1/($E$3:E14<>""), $E$3:E14)) + B15 - D15) -> 3882
A16: 46078 | C16: =IF(B16="", "", SUM($B$4:B16)) | D16: 1000 | E16: =IF(AND(B16="", D16=""), "", N(LOOKUP(2, 1/($E$3:E15<>""), $E$3:E15)) + B16 - D16) -> 2882
A17: 46107 | B17: 17600 | C17: =IF(B17="", "", SUM($B$4:B17)) -> 34482 | E17: =IF(AND(B17="", D17=""), "", N(LOOKUP(2, 1/($E$3:E16<>""), $E$3:E16)) + B17 - D17) -> 20482
A18: 46107 | C18: =IF(B18="", "", SUM($B$4:B18)) | D18: 8000 | E18: =IF(AND(B18="", D18=""), "", N(LOOKUP(2, 1/($E$3:E17<>""), $E$3:E17)) + B18 - D18) -> 12482
A19: 46113 | C19: =IF(B19="", "", SUM($B$4:B19)) | D19: 2000 | E19: =IF(AND(B19="", D19=""), "", N(LOOKUP(2, 1/($E$3:E18<>""), $E$3:E18)) + B19 - D19) -> 10482
A20: 46114 | B20: 20790 | C20: =IF(B20="", "", SUM($B$4:B20)) -> 55272 | E20: =IF(AND(B20="", D20=""), "", N(LOOKUP(2, 1/($E$3:E19<>""), $E$3:E19)) + B20 - D20) -> 31272
A21: 46120 | C21: =IF(B21="", "", SUM($B$4:B21)) | D21: 3000 | E21: =IF(AND(B21="", D21=""), "", N(LOOKUP(2, 1/($E$3:E20<>""), $E$3:E20)) + B21 - D21) -> 28272
A22: 46134 | C22: =IF(B22="", "", SUM($B$4:B22)) | D22: 3000 | E22: =IF(AND(B22="", D22=""), "", N(LOOKUP(2, 1/($E$3:E21<>""), $E$3:E21)) + B22 - D22) -> 25272
A23: 46148 | C23: =IF(B23="", "", SUM($B$4:B23)) | D23: 2500 | E23: =IF(AND(B23="", D23=""), "", N(LOOKUP(2, 1/($E$3:E22<>""), $E$3:E22)) + B23 - D23) -> 22772
A24: 46152 | B24: 8344 | C24: =IF(B24="", "", SUM($B$4:B24)) -> 63616 | E24: =IF(AND(B24="", D24=""), "", N(LOOKUP(2, 1/($E$3:E23<>""), $E$3:E23)) + B24 - D24) -> 31116
A25: 46152 | C25: =IF(B25="", "", SUM($B$4:B25)) | D25: 3000 | E25: =IF(AND(B25="", D25=""), "", N(LOOKUP(2, 1/($E$3:E24<>""), $E$3:E24)) + B25 - D25) -> 28116
A26: 46155 | C26: =IF(B26="", "", SUM($B$4:B26)) | D26: 2000 | E26: =IF(AND(B26="", D26=""), "", N(LOOKUP(2, 1/($E$3:E25<>""), $E$3:E25)) + B26 - D26) -> 26116
A27: 46176 | C27: =IF(B27="", "", SUM($B$4:B27)) | D27: 2000 | E27: =IF(AND(B27="", D27=""), "", N(LOOKUP(2, 1/($E$3:E26<>""), $E$3:E26)) + B27 - D27) -> 24116
A28: 46183 | C28: =IF(B28="", "", SUM($B$4:B28)) | D28: 2000 | E28: =IF(AND(B28="", D28=""), "", N(LOOKUP(2, 1/($E$3:E27<>""), $E$3:E27)) + B28 - D28) -> 22116
C29: =IF(B29="", "", SUM($B$4:B29)) | E29: =IF(AND(B29="", D29=""), "", N(LOOKUP(2, 1/($E$3:E28<>""), $E$3:E28)) + B29 - D29)
C30: =IF(B30="", "", SUM($B$4:B30)) | E30: =IF(AND(B30="", D30=""), "", N(LOOKUP(2, 1/($E$3:E29<>""), $E$3:E29)) + B30 - D30)
C31: =IF(B31="", "", SUM($B$4:B31)) | E31: =IF(AND(B31="", D31=""), "", N(LOOKUP(2, 1/($E$3:E30<>""), $E$3:E30)) + B31 - D31)
C32: =IF(B32="", "", SUM($B$4:B32)) | E32: =IF(AND(B32="", D32=""), "", N(LOOKUP(2, 1/($E$3:E31<>""), $E$3:E31)) + B32 - D32)
C33: =IF(B33="", "", SUM($B$4:B33)) | E33: =IF(AND(B33="", D33=""), "", N(LOOKUP(2, 1/($E$3:E32<>""), $E$3:E32)) + B33 - D33)
C34: =IF(B34="", "", SUM($B$4:B34)) | E34: =IF(AND(B34="", D34=""), "", N(LOOKUP(2, 1/($E$3:E33<>""), $E$3:E33)) + B34 - D34)
C35: =IF(B35="", "", SUM($B$4:B35)) | E35: =IF(AND(B35="", D35=""), "", N(LOOKUP(2, 1/($E$3:E34<>""), $E$3:E34)) + B35 - D35)
C36: =IF(B36="", "", SUM($B$4:B36)) | E36: =IF(AND(B36="", D36=""), "", N(LOOKUP(2, 1/($E$3:E35<>""), $E$3:E35)) + B36 - D36)
C37: =IF(B37="", "", SUM($B$4:B37)) | E37: =IF(AND(B37="", D37=""), "", N(LOOKUP(2, 1/($E$3:E36<>""), $E$3:E36)) + B37 - D37)
C38: =IF(B38="", "", SUM($B$4:B38)) | E38: =IF(AND(B38="", D38=""), "", N(LOOKUP(2, 1/($E$3:E37<>""), $E$3:E37)) + B38 - D38)
C39: =IF(B39="", "", SUM($B$4:B39)) | E39: =IF(AND(B39="", D39=""), "", N(LOOKUP(2, 1/($E$3:E38<>""), $E$3:E38)) + B39 - D39)
C40: =IF(B40="", "", SUM($B$4:B40)) | E40: =IF(AND(B40="", D40=""), "", N(LOOKUP(2, 1/($E$3:E39<>""), $E$3:E39)) + B40 - D40)
... C100: =IF(B100="", "", SUM($B$4:B100)) | E100: =IF(AND(B100="", D100=""), "", N(LOOKUP(2, 1/($E$3:E99<>""), $E$3:E99)) + B100 - D100)
...

Sheet Miya
A1: =HYPERLINK("#'Home'!A1", "Home") -> Home | B1: Miya Electric
A3: Date | B3: Product | C3: Total | D3: Deposite | E3: Deu
A4: 45910 | B4: 20704 | C4: =IF(B4="", "", SUM($B$4:B4)) -> 20704 | E4: =IF(AND(B4="", D4=""), "", N(LOOKUP(2, 1/($E$3:E3<>""), $E$3:E3)) + B4 - D4) -> 20704
A5: 45924 | C5: =IF(B5="", "", SUM($B$4:B5)) | D5: 2000 | E5: =IF(AND(B5="", D5=""), "", N(LOOKUP(2, 1/($E$3:E4<>""), $E$3:E4)) + B5 - D5) -> 18704
A6: 45938 | C6: =IF(B6="", "", SUM($B$4:B6)) | D6: 2000 | E6: =IF(AND(B6="", D6=""), "", N(LOOKUP(2, 1/($E$3:E5<>""), $E$3:E5)) + B6 - D6) -> 16704
A7: 45945 | C7: =IF(B7="", "", SUM($B$4:B7)) | D7: 2000 | E7: =IF(AND(B7="", D7=""), "", N(LOOKUP(2, 1/($E$3:E6<>""), $E$3:E6)) + B7 - D7) -> 14704
A8: 45957 | B8: 29200 | C8: =IF(B8="", "", SUM($B$4:B8)) -> 49904 | E8: =IF(AND(B8="", D8=""), "", N(LOOKUP(2, 1/($E$3:E7<>""), $E$3:E7)) + B8 - D8) -> 43904
A9: 45959 | C9: =IF(B9="", "", SUM($B$4:B9)) | D9: 3000 | E9: =IF(AND(B9="", D9=""), "", N(LOOKUP(2, 1/($E$3:E8<>""), $E$3:E8)) + B9 - D9) -> 40904
A10: 45966 | C10: =IF(B10="", "", SUM($B$4:B10)) | D10: 3000 | E10: =IF(AND(B10="", D10=""), "", N(LOOKUP(2, 1/($E$3:E9<>""), $E$3:E9)) + B10 - D10) -> 37904
A11: 45973 | C11: =IF(B11="", "", SUM($B$4:B11)) | D11: 3000 | E11: =IF(AND(B11="", D11=""), "", N(LOOKUP(2, 1/($E$3:E10<>""), $E$3:E10)) + B11 - D11) -> 34904
A12: 45985 | B12: 4800 | C12: =IF(B12="", "", SUM($B$4:B12)) -> 54704 | E12: =IF(AND(B12="", D12=""), "", N(LOOKUP(2, 1/($E$3:E11<>""), $E$3:E11)) + B12 - D12) -> 39704
A13: 45987 | C13: =IF(B13="", "", SUM($B$4:B13)) | D13: 2000 | E13: =IF(AND(B13="", D13=""), "", N(LOOKUP(2, 1/($E$3:E12<>""), $E$3:E12)) + B13 - D13) -> 37704
A14: 45994 | C14: =IF(B14="", "", SUM($B$4:B14)) | D14: 2000 | E14: =IF(AND(B14="", D14=""), "", N(LOOKUP(2, 1/($E$3:E13<>""), $E$3:E13)) + B14 - D14) -> 35704
A15: 45995 | B15: 15890 | C15: =IF(B15="", "", SUM($B$4:B15)) -> 70594 | E15: =IF(AND(B15="", D15=""), "", N(LOOKUP(2, 1/($E$3:E14<>""), $E$3:E14)) + B15 - D15) -> 51594
A16: 46001 | C16: =IF(B16="", "", SUM($B$4:B16)) | D16: 3000 | E16: =IF(AND(B16="", D16=""), "", N(LOOKUP(2, 1/($E$3:E15<>""), $E$3:E15)) + B16 - D16) -> 48594
A17: 46008 | C17: =IF(B17="", "", SUM($B$4:B17)) | D17: 2000 | E17: =IF(AND(B17="", D17=""), "", N(LOOKUP(2, 1/($E$3:E16<>""), $E$3:E16)) + B17 - D17) -> 46594
A18: 46015 | C18: =IF(B18="", "", SUM($B$4:B18)) | D18: 2000 | E18: =IF(AND(B18="", D18=""), "", N(LOOKUP(2, 1/($E$3:E17<>""), $E$3:E17)) + B18 - D18) -> 44594
A19: 46022 | C19: =IF(B19="", "", SUM($B$4:B19)) | D19: 3000 | E19: =IF(AND(B19="", D19=""), "", N(LOOKUP(2, 1/($E$3:E18<>""), $E$3:E18)) + B19 - D19) -> 41594
A20: 46031 | C20: =IF(B20="", "", SUM($B$4:B20)) | D20: 2000 | E20: =IF(AND(B20="", D20=""), "", N(LOOKUP(2, 1/($E$3:E19<>""), $E$3:E19)) + B20 - D20) -> 39594
A21: 46038 | C21: =IF(B21="", "", SUM($B$4:B21)) | D21: 3000 | E21: =IF(AND(B21="", D21=""), "", N(LOOKUP(2, 1/($E$3:E20<>""), $E$3:E20)) + B21 - D21) -> 36594
A22: 46050 | C22: =IF(B22="", "", SUM($B$4:B22)) | D22: 2000 | E22: =IF(AND(B22="", D22=""), "", N(LOOKUP(2, 1/($E$3:E21<>""), $E$3:E21)) + B22 - D22) -> 34594
A23: 46078 | C23: =IF(B23="", "", SUM($B$4:B23)) | D23: 2000 | E23: =IF(AND(B23="", D23=""), "", N(LOOKUP(2, 1/($E$3:E22<>""), $E$3:E22)) + B23 - D23) -> 32594
A24: 46113 | C24: =IF(B24="", "", SUM($B$4:B24)) | D24: 1000 | E24: =IF(AND(B24="", D24=""), "", N(LOOKUP(2, 1/($E$3:E23<>""), $E$3:E23)) + B24 - D24) -> 31594
A25: 46120 | C25: =IF(B25="", "", SUM($B$4:B25)) | D25: 500 | E25: =IF(AND(B25="", D25=""), "", N(LOOKUP(2, 1/($E$3:E24<>""), $E$3:E24)) + B25 - D25) -> 31094
A26: 46127 | C26: =IF(B26="", "", SUM($B$4:B26)) | D26: 1000 | E26: =IF(AND(B26="", D26=""), "", N(LOOKUP(2, 1/($E$3:E25<>""), $E$3:E25)) + B26 - D26) -> 30094
A27: 46141 | C27: =IF(B27="", "", SUM($B$4:B27)) | D27: 3000 | E27: =IF(AND(B27="", D27=""), "", N(LOOKUP(2, 1/($E$3:E26<>""), $E$3:E26)) + B27 - D27) -> 27094
A28: 46148 | C28: =IF(B28="", "", SUM($B$4:B28)) | D28: 2000 | E28: =IF(AND(B28="", D28=""), "", N(LOOKUP(2, 1/($E$3:E27<>""), $E$3:E27)) + B28 - D28) -> 25094
A29: 46152 | B29: 13480 | C29: =IF(B29="", "", SUM($B$4:B29)) -> 84074 | E29: =IF(AND(B29="", D29=""), "", N(LOOKUP(2, 1/($E$3:E28<>""), $E$3:E28)) + B29 - D29) -> 38574
A30: 46155 | C30: =IF(B30="", "", SUM($B$4:B30)) | D30: 3000 | E30: =IF(AND(B30="", D30=""), "", N(LOOKUP(2, 1/($E$3:E29<>""), $E$3:E29)) + B30 - D30) -> 35574
A31: 46162 | C31: =IF(B31="", "", SUM($B$4:B31)) | D31: 3000 | E31: =IF(AND(B31="", D31=""), "", N(LOOKUP(2, 1/($E$3:E30<>""), $E$3:E30)) + B31 - D31) -> 32574 | F31: Bkash
A32: 46176 | C32: =IF(B32="", "", SUM($B$4:B32)) | D32: 2000 | E32: =IF(AND(B32="", D32=""), "", N(LOOKUP(2, 1/($E$3:E31<>""), $E$3:E31)) + B32 - D32) -> 30574
A33: 46183 | C33: =IF(B33="", "", SUM($B$4:B33)) | D33: 3000 | E33: =IF(AND(B33="", D33=""), "", N(LOOKUP(2, 1/($E$3:E32<>""), $E$3:E32)) + B33 - D33) -> 27574
A34: 46187 | C34: =IF(B34="", "", SUM($B$4:B34)) | D34: 2000 | E34: =IF(AND(B34="", D34=""), "", N(LOOKUP(2, 1/($E$3:E33<>""), $E$3:E33)) + B34 - D34) -> 25574 | F34: Bkash
C35: =IF(B35="", "", SUM($B$4:B35)) | E35: =IF(AND(B35="", D35=""), "", N(LOOKUP(2, 1/($E$3:E34<>""), $E$3:E34)) + B35 - D35)
C36: =IF(B36="", "", SUM($B$4:B36)) | E36: =IF(AND(B36="", D36=""), "", N(LOOKUP(2, 1/($E$3:E35<>""), $E$3:E35)) + B36 - D36)
C37: =IF(B37="", "", SUM($B$4:B37)) | E37: =IF(AND(B37="", D37=""), "", N(LOOKUP(2, 1/($E$3:E36<>""), $E$3:E36)) + B37 - D37)
C38: =IF(B38="", "", SUM($B$4:B38)) | E38: =IF(AND(B38="", D38=""), "", N(LOOKUP(2, 1/($E$3:E37<>""), $E$3:E37)) + B38 - D38)
C39: =IF(B39="", "", SUM($B$4:B39)) | E39: =IF(AND(B39="", D39=""), "", N(LOOKUP(2, 1/($E$3:E38<>""), $E$3:E38)) + B39 - D39)
C40: =IF(B40="", "", SUM($B$4:B40)) | E40: =IF(AND(B40="", D40=""), "", N(LOOKUP(2, 1/($E$3:E39<>""), $E$3:E39)) + B40 - D40)
C41: =IF(B41="", "", SUM($B$4:B41)) | E41: =IF(AND(B41="", D41=""), "", N(LOOKUP(2, 1/($E$3:E40<>""), $E$3:E40)) + B41 - D41)
...

Sheet Rafid
B1: Rafid Crockery
A3: Date | B3: Product | C3: Total | D3: Deposite | E3: Deu
A4: 45910 | B4: 3780 | C4: =IF(B4="", "", SUM($B$4:B4)) -> 3780 | E4: =IF(AND(B4="", D4=""), "", N(LOOKUP(2, 1/($E$3:E3<>""), $E$3:E3)) + B4 - D4) -> 3780
A5: 45924 | C5: =IF(B5="", "", SUM($B$4:B5)) | D5: 2000 | E5: =IF(AND(B5="", D5=""), "", N(LOOKUP(2, 1/($E$3:E4<>""), $E$3:E4)) + B5 - D5) -> 1780
A6: 45938 | C6: =IF(B6="", "", SUM($B$4:B6)) | D6: 1700 | E6: =IF(AND(B6="", D6=""), "", N(LOOKUP(2, 1/($E$3:E5<>""), $E$3:E5)) + B6 - D6) -> 80
A7: 45945 | B7: 4620 | C7: =IF(B7="", "", SUM($B$4:B7)) -> 8400 | E7: =IF(AND(B7="", D7=""), "", N(LOOKUP(2, 1/($E$3:E6<>""), $E$3:E6)) + B7 - D7) -> 4700
A8: 45945 | C8: =IF(B8="", "", SUM($B$4:B8)) | D8: 1520 | E8: =IF(AND(B8="", D8=""), "", N(LOOKUP(2, 1/($E$3:E7<>""), $E$3:E7)) + B8 - D8) -> 3180
A9: 45957 | B9: 9720 | C9: =IF(B9="", "", SUM($B$4:B9)) -> 18120 | E9: =IF(AND(B9="", D9=""), "", N(LOOKUP(2, 1/($E$3:E8<>""), $E$3:E8)) + B9 - D9) -> 12900
A10: 45973 | C10: =IF(B10="", "", SUM($B$4:B10)) | D10: 1500 | E10: =IF(AND(B10="", D10=""), "", N(LOOKUP(2, 1/($E$3:E9<>""), $E$3:E9)) + B10 - D10) -> 11400
A11: 45980 | C11: =IF(B11="", "", SUM($B$4:B11)) | D11: 2000 | E11: =IF(AND(B11="", D11=""), "", N(LOOKUP(2, 1/($E$3:E10<>""), $E$3:E10)) + B11 - D11) -> 9400
A12: 45994 | C12: =IF(B12="", "", SUM($B$4:B12)) | D12: 1000 | E12: =IF(AND(B12="", D12=""), "", N(LOOKUP(2, 1/($E$3:E11<>""), $E$3:E11)) + B12 - D12) -> 8400
A13: 46008 | C13: =IF(B13="", "", SUM($B$4:B13)) | D13: 2000 | E13: =IF(AND(B13="", D13=""), "", N(LOOKUP(2, 1/($E$3:E12<>""), $E$3:E12)) + B13 - D13) -> 6400
A14: 46022 | C14: =IF(B14="", "", SUM($B$4:B14)) | D14: 2500 | E14: =IF(AND(B14="", D14=""), "", N(LOOKUP(2, 1/($E$3:E13<>""), $E$3:E13)) + B14 - D14) -> 3900
A15: 46022 | B15: 2460 | C15: =IF(B15="", "", SUM($B$4:B15)) -> 20580 | E15: =IF(AND(B15="", D15=""), "", N(LOOKUP(2, 1/($E$3:E14<>""), $E$3:E14)) + B15 - D15) -> 6360
A16: 46026 | B16: 19440 | C16: =IF(B16="", "", SUM($B$4:B16)) -> 40020 | E16: =IF(AND(B16="", D16=""), "", N(LOOKUP(2, 1/($E$3:E15<>""), $E$3:E15)) + B16 - D16) -> 25800
A17: 46029 | C17: =IF(B17="", "", SUM($B$4:B17)) | D17: 2580 | E17: =IF(AND(B17="", D17=""), "", N(LOOKUP(2, 1/($E$3:E16<>""), $E$3:E16)) + B17 - D17) -> 23220
A18: 46036 | C18: =IF(B18="", "", SUM($B$4:B18)) | D18: 2000 | E18: =IF(AND(B18="", D18=""), "", N(LOOKUP(2, 1/($E$3:E17<>""), $E$3:E17)) + B18 - D18) -> 21220
A19: 46043 | C19: =IF(B19="", "", SUM($B$4:B19)) | D19: 1220 | E19: =IF(AND(B19="", D19=""), "", N(LOOKUP(2, 1/($E$3:E18<>""), $E$3:E18)) + B19 - D19) -> 20000
A20: 46057 | C20: =IF(B20="", "", SUM($B$4:B20)) | D20: 1500 | E20: =IF(AND(B20="", D20=""), "", N(LOOKUP(2, 1/($E$3:E19<>""), $E$3:E19)) + B20 - D20) -> 18500
A21: 46085 | C21: =IF(B21="", "", SUM($B$4:B21)) | D21: 2500 | E21: =IF(AND(B21="", D21=""), "", N(LOOKUP(2, 1/($E$3:E20<>""), $E$3:E20)) + B21 - D21) -> 16000
A22: 46092 | B22: 2260 | C22: =IF(B22="", "", SUM($B$4:B22)) -> 42280 | E22: =IF(AND(B22="", D22=""), "", N(LOOKUP(2, 1/($E$3:E21<>""), $E$3:E21)) + B22 - D22) -> 18260
A23: 46092 | C23: =IF(B23="", "", SUM($B$4:B23)) | D23: 8620 | E23: =IF(AND(B23="", D23=""), "", N(LOOKUP(2, 1/($E$3:E22<>""), $E$3:E22)) + B23 - D23) -> 9640
A24: 46092 | C24: =IF(B24="", "", SUM($B$4:B24)) | D24: 1600 | E24: =IF(AND(B24="", D24=""), "", N(LOOKUP(2, 1/($E$3:E23<>""), $E$3:E23)) + B24 - D24) -> 8040
A25: 46093 | B25: 17628 | C25: =IF(B25="", "", SUM($B$4:B25)) -> 59908 | E25: =IF(AND(B25="", D25=""), "", N(LOOKUP(2, 1/($E$3:E24<>""), $E$3:E24)) + B25 - D25) -> 25668
A26: 25/mar/26 | C26: =IF(B26="", "", SUM($B$4:B26)) | D26: 2000 | E26: =IF(AND(B26="", D26=""), "", N(LOOKUP(2, 1/($E$3:E25<>""), $E$3:E25)) + B26 - D26) -> 23668
B27: 5140 | C27: =IF(B27="", "", SUM($B$4:B27)) -> 65048 | E27: =IF(AND(B27="", D27=""), "", N(LOOKUP(2, 1/($E$3:E26<>""), $E$3:E26)) + B27 - D27) -> 28808
A28: 46120 | C28: =IF(B28="", "", SUM($B$4:B28)) | D28: 1808 | E28: =IF(AND(B28="", D28=""), "", N(LOOKUP(2, 1/($E$3:E27<>""), $E$3:E27)) + B28 - D28) -> 27000
A29: 46134 | C29: =IF(B29="", "", SUM($B$4:B29)) | D29: 1000 | E29: =IF(AND(B29="", D29=""), "", N(LOOKUP(2, 1/($E$3:E28<>""), $E$3:E28)) + B29 - D29) -> 26000
A30: 46141 | C30: =IF(B30="", "", SUM($B$4:B30)) | D30: 1000 | E30: =IF(AND(B30="", D30=""), "", N(LOOKUP(2, 1/($E$3:E29<>""), $E$3:E29)) + B30 - D30) -> 25000
A31: 46148 | C31: =IF(B31="", "", SUM($B$4:B31)) | D31: 1000 | E31: =IF(AND(B31="", D31=""), "", N(LOOKUP(2, 1/($E$3:E30<>""), $E$3:E30)) + B31 - D31) -> 24000
A32: 46148 | B32: 441 | C32: =IF(B32="", "", SUM($B$4:B32)) -> 65489 | E32: =IF(AND(B32="", D32=""), "", N(LOOKUP(2, 1/($E$3:E31<>""), $E$3:E31)) + B32 - D32) -> 24441
A33: 46162 | C33: =IF(B33="", "", SUM($B$4:B33)) | D33: 2441 | E33: =IF(AND(B33="", D33=""), "", N(LOOKUP(2, 1/($E$3:E32<>""), $E$3:E32)) + B33 - D33) -> 22000
A34: 46176 | C34: =IF(B34="", "", SUM($B$4:B34)) | D34: 3000 | E34: =IF(AND(B34="", D34=""), "", N(LOOKUP(2, 1/($E$3:E33<>""), $E$3:E33)) + B34 - D34) -> 19000
A35: 46183 | C35: =IF(B35="", "", SUM($B$4:B35)) | D35: 3000 | E35: =IF(AND(B35="", D35=""), "", N(LOOKUP(2, 1/($E$3:E34<>""), $E$3:E34)) + B35 - D35) -> 16000
C36: =IF(B36="", "", SUM($B$4:B36)) | E36: =IF(AND(B36="", D36=""), "", N(LOOKUP(2, 1/($E$3:E35<>""), $E$3:E35)) + B36 - D36)
C37: =IF(B37="", "", SUM($B$4:B37)) | E37: =IF(AND(B37="", D37=""), "", N(LOOKUP(2, 1/($E$3:E36<>""), $E$3:E36)) + B37 - D37)
C38: =IF(B38="", "", SUM($B$4:B38)) | E38: =IF(AND(B38="", D38=""), "", N(LOOKUP(2, 1/($E$3:E37<>""), $E$3:E37)) + B38 - D38)
C39: =IF(B39="", "", SUM($B$4:B39)) | E39: =IF(AND(B39="", D39=""), "", N(LOOKUP(2, 1/($E$3:E38<>""), $E$3:E38)) + B39 - D39)
C40: =IF(B40="", "", SUM($B$4:B40)) | E40: =IF(AND(B40="", D40=""), "", N(LOOKUP(2, 1/($E$3:E39<>""), $E$3:E39)) + B40 - D40)
C41: =IF(B41="", "", SUM($B$4:B41)) | E41: =IF(AND(B41="", D41=""), "", N(LOOKUP(2, 1/($E$3:E40<>""), $E$3:E40)) + B41 - D41)
...

Sheet Fatema
A1: =HYPERLINK("#'Home'!A1", "Home") -> Home | B1: Fatema Electric
A3: Date | B3: Product | C3: Total | D3: Deposite | E3: Deu
A4: 45924 | B4: 15254 | C4: =IF(B4="", "", SUM($B$4:B4)) -> 15254 | E4: =IF(AND(B4="", D4=""), "", N(LOOKUP(2, 1/($E$3:E3<>""), $E$3:E3)) + B4 - D4) -> 15254
A5: 45938 | C5: =IF(B5="", "", SUM($B$4:B5)) | D5: 2000 | E5: =IF(AND(B5="", D5=""), "", N(LOOKUP(2, 1/($E$3:E4<>""), $E$3:E4)) + B5 - D5) -> 13254
A6: 45945 | C6: =IF(B6="", "", SUM($B$4:B6)) | D6: 3000 | E6: =IF(AND(B6="", D6=""), "", N(LOOKUP(2, 1/($E$3:E5<>""), $E$3:E5)) + B6 - D6) -> 10254
A7: 45952 | C7: =IF(B7="", "", SUM($B$4:B7)) | D7: 200 | E7: =IF(AND(B7="", D7=""), "", N(LOOKUP(2, 1/($E$3:E6<>""), $E$3:E6)) + B7 - D7) -> 10054 | F7: ASM Discount-200/-
A8: 45959 | B8: 1974 | C8: =IF(B8="", "", SUM($B$4:B8)) -> 17228 | E8: =IF(AND(B8="", D8=""), "", N(LOOKUP(2, 1/($E$3:E7<>""), $E$3:E7)) + B8 - D8) -> 12028
A9: 45966 | C9: =IF(B9="", "", SUM($B$4:B9)) | D9: 4000 | E9: =IF(AND(B9="", D9=""), "", N(LOOKUP(2, 1/($E$3:E8<>""), $E$3:E8)) + B9 - D9) -> 8028
A10: 45973 | C10: =IF(B10="", "", SUM($B$4:B10)) | D10: 4000 | E10: =IF(AND(B10="", D10=""), "", N(LOOKUP(2, 1/($E$3:E9<>""), $E$3:E9)) + B10 - D10) -> 4028
A11: 45980 | C11: =IF(B11="", "", SUM($B$4:B11)) | D11: 2000 | E11: =IF(AND(B11="", D11=""), "", N(LOOKUP(2, 1/($E$3:E10<>""), $E$3:E10)) + B11 - D11) -> 2028
A12: 45987 | C12: =IF(B12="", "", SUM($B$4:B12)) | D12: 1000 | E12: =IF(AND(B12="", D12=""), "", N(LOOKUP(2, 1/($E$3:E11<>""), $E$3:E11)) + B12 - D12) -> 1028
A13: 45994 | B13: 968 | C13: =IF(B13="", "", SUM($B$4:B13)) -> 18196 | E13: =IF(AND(B13="", D13=""), "", N(LOOKUP(2, 1/($E$3:E12<>""), $E$3:E12)) + B13 - D13) -> 1996
A14: 46008 | C14: =IF(B14="", "", SUM($B$4:B14)) | D14: 1300 | E14: =IF(AND(B14="", D14=""), "", N(LOOKUP(2, 1/($E$3:E13<>""), $E$3:E13)) + B14 - D14) -> 696 | F14: 1.8 SS K/Y Adjust-1300/-
A15: 46008 | C15: =IF(B15="", "", SUM($B$4:B15)) | D15: 696 | E15: =IF(AND(B15="", D15=""), "", N(LOOKUP(2, 1/($E$3:E14<>""), $E$3:E14)) + B15 - D15) -> 0
A16: 46071 | B16: 8955 | C16: =IF(B16="", "", SUM($B$4:B16)) -> 27151 | E16: =IF(AND(B16="", D16=""), "", N(LOOKUP(2, 1/($E$3:E15<>""), $E$3:E15)) + B16 - D16) -> 8955
A17: 46071 | C17: =IF(B17="", "", SUM($B$4:B17)) | D17: 8955 | E17: =IF(AND(B17="", D17=""), "", N(LOOKUP(2, 1/($E$3:E16<>""), $E$3:E16)) + B17 - D17) -> 0
C18: =IF(B18="", "", SUM($B$4:B18)) | E18: =IF(AND(B18="", D18=""), "", N(LOOKUP(2, 1/($E$3:E17<>""), $E$3:E17)) + B18 - D18)
C19: =IF(B19="", "", SUM($B$4:B19)) | E19: =IF(AND(B19="", D19=""), "", N(LOOKUP(2, 1/($E$3:E18<>""), $E$3:E18)) + B19 - D19)
C20: =IF(B20="", "", SUM($B$4:B20)) | E20: =IF(AND(B20="", D20=""), "", N(LOOKUP(2, 1/($E$3:E19<>""), $E$3:E19)) + B20 - D20)
A21: 46085 | C21: =IF(B21="", "", SUM($B$4:B21)) | D21: 90000 | E21: =IF(AND(B21="", D21=""), "", N(LOOKUP(2, 1/($E$3:E20<>""), $E$3:E20)) + B21 - D21) -> -90000
A22: 46089 | B22: 8871 | C22: =IF(B22="", "", SUM($B$4:B22)) -> 36022 | E22: =IF(AND(B22="", D22=""), "", N(LOOKUP(2, 1/($E$3:E21<>""), $E$3:E21)) + B22 - D22) -> -81129
A23: 46089 | B23: 20203 | C23: =IF(B23="", "", SUM($B$4:B23)) -> 56225 | E23: =IF(AND(B23="", D23=""), "", N(LOOKUP(2, 1/($E$3:E22<>""), $E$3:E22)) + B23 - D23) -> -60926
A24: 46089 | B24: 15705 | C24: =IF(B24="", "", SUM($B$4:B24)) -> 71930 | E24: =IF(AND(B24="", D24=""), "", N(LOOKUP(2, 1/($E$3:E23<>""), $E$3:E23)) + B24 - D24) -> -45221
A25: 46089 | B25: 8871 | C25: =IF(B25="", "", SUM($B$4:B25)) -> 80801 | E25: =IF(AND(B25="", D25=""), "", N(LOOKUP(2, 1/($E$3:E24<>""), $E$3:E24)) + B25 - D25) -> -36350
A26: 46089 | B26: 8935 | C26: =IF(B26="", "", SUM($B$4:B26)) -> 89736 | E26: =IF(AND(B26="", D26=""), "", N(LOOKUP(2, 1/($E$3:E25<>""), $E$3:E25)) + B26 - D26) -> -27415
A27: 46089 | B27: 18350 | C27: =IF(B27="", "", SUM($B$4:B27)) -> 108086 | E27: =IF(AND(B27="", D27=""), "", N(LOOKUP(2, 1/($E$3:E26<>""), $E$3:E26)) + B27 - D27) -> -9065
A28: 46099 | B28: 24602 | C28: =IF(B28="", "", SUM($B$4:B28)) -> 132688 | E28: =IF(AND(B28="", D28=""), "", N(LOOKUP(2, 1/($E$3:E27<>""), $E$3:E27)) + B28 - D28) -> 15537
A29: 46099 | B29: 32761 | C29: =IF(B29="", "", SUM($B$4:B29)) -> 165449 | E29: =IF(AND(B29="", D29=""), "", N(LOOKUP(2, 1/($E$3:E28<>""), $E$3:E28)) + B29 - D29) -> 48298
A30: 46114 | C30: =IF(B30="", "", SUM($B$4:B30)) | D30: 20000 | E30: =IF(AND(B30="", D30=""), "", N(LOOKUP(2, 1/($E$3:E29<>""), $E$3:E29)) + B30 - D30) -> 28298
A31: 46134 | C31: =IF(B31="", "", SUM($B$4:B31)) | D31: 60000 | E31: =IF(AND(B31="", D31=""), "", N(LOOKUP(2, 1/($E$3:E30<>""), $E$3:E30)) + B31 - D31) -> -31702
A32: 46138 | B32: 19355 | C32: =IF(B32="", "", SUM($B$4:B32)) -> 184804 | E32: =IF(AND(B32="", D32=""), "", N(LOOKUP(2, 1/($E$3:E31<>""), $E$3:E31)) + B32 - D32) -> -12347
A33: 46138 | B33: 5260 | C33: =IF(B33="", "", SUM($B$4:B33)) -> 190064 | E33: =IF(AND(B33="", D33=""), "", N(LOOKUP(2, 1/($E$3:E32<>""), $E$3:E32)) + B33 - D33) -> -7087
A34: 46138 | B34: 7057 | C34: =IF(B34="", "", SUM($B$4:B34)) -> 197121 | E34: =IF(AND(B34="", D34=""), "", N(LOOKUP(2, 1/($E$3:E33<>""), $E$3:E33)) + B34 - D34) -> -30
A35: 46138 | B35: 27238 | C35: =IF(B35="", "", SUM($B$4:B35)) -> 224359 | E35: =IF(AND(B35="", D35=""), "", N(LOOKUP(2, 1/($E$3:E34<>""), $E$3:E34)) + B35 - D35) -> 27208
A36: 46146 | B36: 13100 | C36: =IF(B36="", "", SUM($B$4:B36)) -> 237459 | E36: =IF(AND(B36="", D36=""), "", N(LOOKUP(2, 1/($E$3:E35<>""), $E$3:E35)) + B36 - D36) -> 40308
A37: 46146 | B37: 7777 | C37: =IF(B37="", "", SUM($B$4:B37)) -> 245236 | E37: =IF(AND(B37="", D37=""), "", N(LOOKUP(2, 1/($E$3:E36<>""), $E$3:E36)) + B37 - D37) -> 48085
A38: 46151 | B38: 31812 | C38: =IF(B38="", "", SUM($B$4:B38)) -> 277048 | E38: =IF(AND(B38="", D38=""), "", N(LOOKUP(2, 1/($E$3:E37<>""), $E$3:E37)) + B38 - D38) -> 79897
A39: 46176 | C39: =IF(B39="", "", SUM($B$4:B39)) | D39: 30000 | E39: =IF(AND(B39="", D39=""), "", N(LOOKUP(2, 1/($E$3:E38<>""), $E$3:E38)) + B39 - D39) -> 49897 | F39: ASM
A40: 46188 | B40: 18852 | C40: =IF(B40="", "", SUM($B$4:B40)) -> 295900 | E40: =IF(AND(B40="", D40=""), "", N(LOOKUP(2, 1/($E$3:E39<>""), $E$3:E39)) + B40 - D40) -> 68749
A41: 46188 | B41: 8935 | C41: =IF(B41="", "", SUM($B$4:B41)) -> 304835 | E41: =IF(AND(B41="", D41=""), "", N(LOOKUP(2, 1/($E$3:E40<>""), $E$3:E40)) + B41 - D41) -> 77684
...

Sheet Badhon
A1: =HYPERLINK("#'Home'!A1", "Home") -> Home | B1: Badhon Electric
A3: Date | B3: Product | C3: Total | D3: Deposite | E3: Deu
A4: 45995 | B4: 18000 | C4: =IF(B4="", "", SUM($B$4:B4)) -> 18000 | E4: =IF(AND(B4="", D4=""), "", N(LOOKUP(2, 1/($E$3:E3<>""), $E$3:E3)) + B4 - D4) -> 18000
A5: 46001 | C5: =IF(B5="", "", SUM($B$4:B5)) | D5: 18000 | E5: =IF(AND(B5="", D5=""), "", N(LOOKUP(2, 1/($E$3:E4<>""), $E$3:E4)) + B5 - D5) -> 0
A6: 46026 | B6: 45800 | C6: =IF(B6="", "", SUM($B$4:B6)) -> 63800 | E6: =IF(AND(B6="", D6=""), "", N(LOOKUP(2, 1/($E$3:E5<>""), $E$3:E5)) + B6 - D6) -> 45800
A7: 46026 | C7: =IF(B7="", "", SUM($B$4:B7)) | D7: 45800 | E7: =IF(AND(B7="", D7=""), "", N(LOOKUP(2, 1/($E$3:E6<>""), $E$3:E6)) + B7 - D7) -> 0
C8: =IF(B8="", "", SUM($B$4:B8)) | E8: =IF(AND(B8="", D8=""), "", N(LOOKUP(2, 1/($E$3:E7<>""), $E$3:E7)) + B8 - D8)
C9: =IF(B9="", "", SUM($B$4:B9)) | E9: =IF(AND(B9="", D9=""), "", N(LOOKUP(2, 1/($E$3:E8<>""), $E$3:E8)) + B9 - D9)
C10: =IF(B10="", "", SUM($B$4:B10)) | E10: =IF(AND(B10="", D10=""), "", N(LOOKUP(2, 1/($E$3:E9<>""), $E$3:E9)) + B10 - D10)
C11: =IF(B11="", "", SUM($B$4:B11)) | E11: =IF(AND(B11="", D11=""), "", N(LOOKUP(2, 1/($E$3:E10<>""), $E$3:E10)) + B11 - D11)
C12: =IF(B12="", "", SUM($B$4:B12)) | E12: =IF(AND(B12="", D12=""), "", N(LOOKUP(2, 1/($E$3:E11<>""), $E$3:E11)) + B12 - D12)
C13: =IF(B13="", "", SUM($B$4:B13)) | E13: =IF(AND(B13="", D13=""), "", N(LOOKUP(2, 1/($E$3:E12<>""), $E$3:E12)) + B13 - D13)
C14: =IF(B14="", "", SUM($B$4:B14)) | E14: =IF(AND(B14="", D14=""), "", N(LOOKUP(2, 1/($E$3:E13<>""), $E$3:E13)) + B14 - D14)
C15: =IF(B15="", "", SUM($B$4:B15)) | E15: =IF(AND(B15="", D15=""), "", N(LOOKUP(2, 1/($E$3:E14<>""), $E$3:E14)) + B15 - D15)
C16: =IF(B16="", "", SUM($B$4:B16)) | E16: =IF(AND(B16="", D16=""), "", N(LOOKUP(2, 1/($E$3:E15<>""), $E$3:E15)) + B16 - D16)
C17: =IF(B17="", "", SUM($B$4:B17)) | E17: =IF(AND(B17="", D17=""), "", N(LOOKUP(2, 1/($E$3:E16<>""), $E$3:E16)) + B17 - D17)
C18: =IF(B18="", "", SUM($B$4:B18)) | E18: =IF(AND(B18="", D18=""), "", N(LOOKUP(2, 1/($E$3:E17<>""), $E$3:E17)) + B18 - D18)
C19: =IF(B19="", "", SUM($B$4:B19)) | E19: =IF(AND(B19="", D19=""), "", N(LOOKUP(2, 1/($E$3:E18<>""), $E$3:E18)) + B19 - D19)
... C100: =IF(B100="", "", SUM($B$4:B100)) | E100: =IF(AND(B100="", D100=""), "", N(LOOKUP(2, 1/($E$3:E99<>""), $E$3:E99)) + B100 - D100)
C101: =IF(B101="", "", SUM($B$4:B101)) | E101: =IF(AND(B101="", D101=""), "", SUM($B$4:B101) - SUM($D$4:D101))
C102: =IF(B102="", "", SUM($B$4:B102)) | E102: =IF(AND(B102="", D102=""), "", SUM($B$4:B102) - SUM($D$4:D102))

Sheet Alam
A1: =HYPERLINK("#'Home'!A1", "Home") -> Home | B1: Alam Plastic
A3: Date | B3: Product | C3: Total | D3: Deposite | E3: Deu
A4: 46036 | B4: 2450 | C4: =IF(B4="", "", SUM($B$4:B4)) -> 2450 | E4: =IF(AND(B4="", D4=""), "", N(LOOKUP(2, 1/($E$3:E3<>""), $E$3:E3)) + B4 - D4) -> 2450
A5: 46036 | C5: =IF(B5="", "", SUM($B$4:B5)) | D5: 1000 | E5: =IF(AND(B5="", D5=""), "", N(LOOKUP(2, 1/($E$3:E4<>""), $E$3:E4)) + B5 - D5) -> 1450
A6: 46065 | C6: =IF(B6="", "", SUM($B$4:B6)) | D6: 1450 | E6: =IF(AND(B6="", D6=""), "", N(LOOKUP(2, 1/($E$3:E5<>""), $E$3:E5)) + B6 - D6) -> 0
B7: 4900 | C7: =IF(B7="", "", SUM($B$4:B7)) -> 7350 | E7: =IF(AND(B7="", D7=""), "", N(LOOKUP(2, 1/($E$3:E6<>""), $E$3:E6)) + B7 - D7) -> 4900
A8: 46134 | C8: =IF(B8="", "", SUM($B$4:B8)) | D8: 1000 | E8: =IF(AND(B8="", D8=""), "", N(LOOKUP(2, 1/($E$3:E7<>""), $E$3:E7)) + B8 - D8) -> 3900
A9: 46148 | C9: =IF(B9="", "", SUM($B$4:B9)) | D9: 1000 | E9: =IF(AND(B9="", D9=""), "", N(LOOKUP(2, 1/($E$3:E8<>""), $E$3:E8)) + B9 - D9) -> 2900
A10: 46152 | B10: 4512 | C10: =IF(B10="", "", SUM($B$4:B10)) -> 11862 | E10: =IF(AND(B10="", D10=""), "", N(LOOKUP(2, 1/($E$3:E9<>""), $E$3:E9)) + B10 - D10) -> 7412
A11: 46152 | C11: =IF(B11="", "", SUM($B$4:B11)) | D11: 1680 | E11: =IF(AND(B11="", D11=""), "", N(LOOKUP(2, 1/($E$3:E10<>""), $E$3:E10)) + B11 - D11) -> 5732
A12: 38871 | C12: =IF(B12="", "", SUM($B$4:B12)) | D12: 1000 | E12: =IF(AND(B12="", D12=""), "", N(LOOKUP(2, 1/($E$3:E11<>""), $E$3:E11)) + B12 - D12) -> 4732
C13: =IF(B13="", "", SUM($B$4:B13)) | E13: =IF(AND(B13="", D13=""), "", N(LOOKUP(2, 1/($E$3:E12<>""), $E$3:E12)) + B13 - D13)
C14: =IF(B14="", "", SUM($B$4:B14)) | E14: =IF(AND(B14="", D14=""), "", N(LOOKUP(2, 1/($E$3:E13<>""), $E$3:E13)) + B14 - D14)
C15: =IF(B15="", "", SUM($B$4:B15)) | E15: =IF(AND(B15="", D15=""), "", N(LOOKUP(2, 1/($E$3:E14<>""), $E$3:E14)) + B15 - D15)
C16: =IF(B16="", "", SUM($B$4:B16)) | E16: =IF(AND(B16="", D16=""), "", N(LOOKUP(2, 1/($E$3:E15<>""), $E$3:E15)) + B16 - D16)
C17: =IF(B17="", "", SUM($B$4:B17)) | E17: =IF(AND(B17="", D17=""), "", N(LOOKUP(2, 1/($E$3:E16<>""), $E$3:E16)) + B17 - D17)
C18: =IF(B18="", "", SUM($B$4:B18)) | E18: =IF(AND(B18="", D18=""), "", N(LOOKUP(2, 1/($E$3:E17<>""), $E$3:E17)) + B18 - D18)
C19: =IF(B19="", "", SUM($B$4:B19)) | E19: =IF(AND(B19="", D19=""), "", N(LOOKUP(2, 1/($E$3:E18<>""), $E$3:E18)) + B19 - D19)
C20: =IF(B20="", "", SUM($B$4:B20)) | E20: =IF(AND(B20="", D20=""), "", N(LOOKUP(2, 1/($E$3:E19<>""), $E$3:E19)) + B20 - D20)
C21: =IF(B21="", "", SUM($B$4:B21)) | E21: =IF(AND(B21="", D21=""), "", N(LOOKUP(2, 1/($E$3:E20<>""), $E$3:E20)) + B21 - D21)
C22: =IF(B22="", "", SUM($B$4:B22)) | E22: =IF(AND(B22="", D22=""), "", N(LOOKUP(2, 1/($E$3:E21<>""), $E$3:E21)) + B22 - D22)
C23: =IF(B23="", "", SUM($B$4:B23)) | E23: =IF(AND(B23="", D23=""), "", N(LOOKUP(2, 1/($E$3:E22<>""), $E$3:E22)) + B23 - D23)
C24: =IF(B24="", "", SUM($B$4:B24)) | E24: =IF(AND(B24="", D24=""), "", N(LOOKUP(2, 1/($E$3:E23<>""), $E$3:E23)) + B24 - D24)
... C100: =IF(B100="", "", SUM($B$4:B100)) | E100: =IF(AND(B100="", D100=""), "", N(LOOKUP(2, 1/($E$3:E99<>""), $E$3:E99)) + B100 - D100)
C101: =IF(B101="", "", SUM($B$4:B101)) | E101: =IF(AND(B101="", D101=""), "", SUM($B$4:B101) - SUM($D$4:D101))
C102: =IF(B102="", "", SUM($B$4:B102)) | E102: =IF(AND(B102="", D102=""), "", SUM($B$4:B102) - SUM($D$4:D102))

Sheet PakAzad
A1: =HYPERLINK("#'Home'!A1", "Home") -> Home | B1: Pak Azad
A3: Date | B3: Product | C3: Total | D3: Deposite | E3: Deu
A4: 45922 | B4: 110626 | C4: =IF(B4="", "", SUM($B$4:B4)) -> 110626 | E4: =IF(AND(B4="", D4=""), "", N(LOOKUP(2, 1/($E$3:E3<>""), $E$3:E3)) + B4 - D4) -> 110626
A5: 45922 | C5: =IF(B5="", "", SUM($B$4:B5)) | D5: 8000 | E5: =IF(AND(B5="", D5=""), "", N(LOOKUP(2, 1/($E$3:E4<>""), $E$3:E4)) + B5 - D5) -> 102626
A6: 45929 | C6: =IF(B6="", "", SUM($B$4:B6)) | D6: 8000 | E6: =IF(AND(B6="", D6=""), "", N(LOOKUP(2, 1/($E$3:E5<>""), $E$3:E5)) + B6 - D6) -> 94626
A7: 45936 | C7: =IF(B7="", "", SUM($B$4:B7)) | D7: 8000 | E7: =IF(AND(B7="", D7=""), "", N(LOOKUP(2, 1/($E$3:E6<>""), $E$3:E6)) + B7 - D7) -> 86626
A8: 45943 | C8: =IF(B8="", "", SUM($B$4:B8)) | D8: 8000 | E8: =IF(AND(B8="", D8=""), "", N(LOOKUP(2, 1/($E$3:E7<>""), $E$3:E7)) + B8 - D8) -> 78626
A9: 45950 | C9: =IF(B9="", "", SUM($B$4:B9)) | D9: 8000 | E9: =IF(AND(B9="", D9=""), "", N(LOOKUP(2, 1/($E$3:E8<>""), $E$3:E8)) + B9 - D9) -> 70626
A10: 45957 | B10: 43056 | C10: =IF(B10="", "", SUM($B$4:B10)) -> 153682 | E10: =IF(AND(B10="", D10=""), "", N(LOOKUP(2, 1/($E$3:E9<>""), $E$3:E9)) + B10 - D10) -> 113682
A11: 45957 | C11: =IF(B11="", "", SUM($B$4:B11)) | D11: 8000 | E11: =IF(AND(B11="", D11=""), "", N(LOOKUP(2, 1/($E$3:E10<>""), $E$3:E10)) + B11 - D11) -> 105682
A12: 45965 | C12: =IF(B12="", "", SUM($B$4:B12)) | D12: 7000 | E12: =IF(AND(B12="", D12=""), "", N(LOOKUP(2, 1/($E$3:E11<>""), $E$3:E11)) + B12 - D12) -> 98682
A13: 45971 | C13: =IF(B13="", "", SUM($B$4:B13)) | D13: 7000 | E13: =IF(AND(B13="", D13=""), "", N(LOOKUP(2, 1/($E$3:E12<>""), $E$3:E12)) + B13 - D13) -> 91682
A14: 45978 | C14: =IF(B14="", "", SUM($B$4:B14)) | D14: 7000 | E14: =IF(AND(B14="", D14=""), "", N(LOOKUP(2, 1/($E$3:E13<>""), $E$3:E13)) + B14 - D14) -> 84682
A15: 45988 | C15: =IF(B15="", "", SUM($B$4:B15)) | D15: 7000 | E15: =IF(AND(B15="", D15=""), "", N(LOOKUP(2, 1/($E$3:E14<>""), $E$3:E14)) + B15 - D15) -> 77682 | F15: Bkash Dada
A16: 45992 | C16: =IF(B16="", "", SUM($B$4:B16)) | D16: 8000 | E16: =IF(AND(B16="", D16=""), "", N(LOOKUP(2, 1/($E$3:E15<>""), $E$3:E15)) + B16 - D16) -> 69682
A17: 45994 | B17: 47506 | C17: =IF(B17="", "", SUM($B$4:B17)) -> 201188 | E17: =IF(AND(B17="", D17=""), "", N(LOOKUP(2, 1/($E$3:E16<>""), $E$3:E16)) + B17 - D17) -> 117188
A18: 45994 | C18: =IF(B18="", "", SUM($B$4:B18)) | D18: 1000 | E18: =IF(AND(B18="", D18=""), "", N(LOOKUP(2, 1/($E$3:E17<>""), $E$3:E17)) + B18 - D18) -> 116188
A19: 46002 | C19: =IF(B19="", "", SUM($B$4:B19)) | D19: 7000 | E19: =IF(AND(B19="", D19=""), "", N(LOOKUP(2, 1/($E$3:E18<>""), $E$3:E18)) + B19 - D19) -> 109188 | F19: Bkash Dada
A20: 46006 | C20: =IF(B20="", "", SUM($B$4:B20)) | D20: 7000 | E20: =IF(AND(B20="", D20=""), "", N(LOOKUP(2, 1/($E$3:E19<>""), $E$3:E19)) + B20 - D20) -> 102188
A21: 46020 | B21: 18732 | C21: =IF(B21="", "", SUM($B$4:B21)) -> 219920 | E21: =IF(AND(B21="", D21=""), "", N(LOOKUP(2, 1/($E$3:E20<>""), $E$3:E20)) + B21 - D21) -> 120920
A22: 46020 | C22: =IF(B22="", "", SUM($B$4:B22)) | D22: 10000 | E22: =IF(AND(B22="", D22=""), "", N(LOOKUP(2, 1/($E$3:E21<>""), $E$3:E21)) + B22 - D22) -> 110920
A23: 46027 | C23: =IF(B23="", "", SUM($B$4:B23)) | D23: 7000 | E23: =IF(AND(B23="", D23=""), "", N(LOOKUP(2, 1/($E$3:E22<>""), $E$3:E22)) + B23 - D23) -> 103920
A24: 46034 | C24: =IF(B24="", "", SUM($B$4:B24)) | D24: 10000 | E24: =IF(AND(B24="", D24=""), "", N(LOOKUP(2, 1/($E$3:E23<>""), $E$3:E23)) + B24 - D24) -> 93920
A25: 46041 | C25: =IF(B25="", "", SUM($B$4:B25)) | D25: 12000 | E25: =IF(AND(B25="", D25=""), "", N(LOOKUP(2, 1/($E$3:E24<>""), $E$3:E24)) + B25 - D25) -> 81920
A26: 46048 | C26: =IF(B26="", "", SUM($B$4:B26)) | D26: 12000 | E26: =IF(AND(B26="", D26=""), "", N(LOOKUP(2, 1/($E$3:E25<>""), $E$3:E25)) + B26 - D26) -> 69920
A27: 46055 | C27: =IF(B27="", "", SUM($B$4:B27)) | D27: 10000 | E27: =IF(AND(B27="", D27=""), "", N(LOOKUP(2, 1/($E$3:E26<>""), $E$3:E26)) + B27 - D27) -> 59920
A28: 46068 | C28: =IF(B28="", "", SUM($B$4:B28)) | D28: 15000 | E28: =IF(AND(B28="", D28=""), "", N(LOOKUP(2, 1/($E$3:E27<>""), $E$3:E27)) + B28 - D28) -> 44920
A29: 46072 | B29: 68900 | C29: =IF(B29="", "", SUM($B$4:B29)) -> 288820 | E29: =IF(AND(B29="", D29=""), "", N(LOOKUP(2, 1/($E$3:E28<>""), $E$3:E28)) + B29 - D29) -> 113820
A30: 46072 | C30: =IF(B30="", "", SUM($B$4:B30)) | D30: 1000 | E30: =IF(AND(B30="", D30=""), "", N(LOOKUP(2, 1/($E$3:E29<>""), $E$3:E29)) + B30 - D30) -> 112820
A31: 46081 | C31: =IF(B31="", "", SUM($B$4:B31)) | D31: 6000 | E31: =IF(AND(B31="", D31=""), "", N(LOOKUP(2, 1/($E$3:E30<>""), $E$3:E30)) + B31 - D31) -> 106820 | F31: BKash Dada
A32: 46084 | C32: =IF(B32="", "", SUM($B$4:B32)) | D32: 8000 | E32: =IF(AND(B32="", D32=""), "", N(LOOKUP(2, 1/($E$3:E31<>""), $E$3:E31)) + B32 - D32) -> 98820
A33: 46096 | C33: =IF(B33="", "", SUM($B$4:B33)) | D33: 10000 | E33: =IF(AND(B33="", D33=""), "", N(LOOKUP(2, 1/($E$3:E32<>""), $E$3:E32)) + B33 - D33) -> 88820
A34: 46108 | C34: =IF(B34="", "", SUM($B$4:B34)) | D34: 8000 | E34: =IF(AND(B34="", D34=""), "", N(LOOKUP(2, 1/($E$3:E33<>""), $E$3:E33)) + B34 - D34) -> 80820 | F34: Bkash Dada
A35: 46111 | C35: =IF(B35="", "", SUM($B$4:B35)) | D35: 8000 | E35: =IF(AND(B35="", D35=""), "", N(LOOKUP(2, 1/($E$3:E34<>""), $E$3:E34)) + B35 - D35) -> 72820
A36: 46118 | C36: =IF(B36="", "", SUM($B$4:B36)) | D36: 8000 | E36: =IF(AND(B36="", D36=""), "", N(LOOKUP(2, 1/($E$3:E35<>""), $E$3:E35)) + B36 - D36) -> 64820
A37: 46125 | C37: =IF(B37="", "", SUM($B$4:B37)) | D37: 10000 | E37: =IF(AND(B37="", D37=""), "", N(LOOKUP(2, 1/($E$3:E36<>""), $E$3:E36)) + B37 - D37) -> 54820
A38: 46139 | C38: =IF(B38="", "", SUM($B$4:B38)) | D38: 10000 | E38: =IF(AND(B38="", D38=""), "", N(LOOKUP(2, 1/($E$3:E37<>""), $E$3:E37)) + B38 - D38) -> 44820
A39: 46146 | C39: =IF(B39="", "", SUM($B$4:B39)) | D39: 4000 | E39: =IF(AND(B39="", D39=""), "", N(LOOKUP(2, 1/($E$3:E38<>""), $E$3:E38)) + B39 - D39) -> 40820
A40: 46156 | C40: =IF(B40="", "", SUM($B$4:B40)) | D40: 6000 | E40: =IF(AND(B40="", D40=""), "", N(LOOKUP(2, 1/($E$3:E39<>""), $E$3:E39)) + B40 - D40) -> 34820 | F40: Bkash Dada
A41: 46163 | B41: 49796 | C41: =IF(B41="", "", SUM($B$4:B41)) -> 338616 | E41: =IF(AND(B41="", D41=""), "", N(LOOKUP(2, 1/($E$3:E40<>""), $E$3:E40)) + B41 - D41) -> 84616
...

Sheet Himel
A1: =HYPERLINK("#'Home'!A1", "Home") -> Home | B1: Himel Electric
A3: Date | B3: Product | C3: Total | D3: Deposite | E3: Deu
A4: 45853 | B4: 2548 | C4: =IF(B4="", "", SUM($B$4:B4)) -> 2548 | E4: =IF(AND(B4="", D4=""), "", N(LOOKUP(2, 1/($E$3:E3<>""), $E$3:E3)) + B4 - D4) -> 2548
A5: 45971 | B5: 4740 | C5: =IF(B5="", "", SUM($B$4:B5)) -> 7288 | E5: =IF(AND(B5="", D5=""), "", N(LOOKUP(2, 1/($E$3:E4<>""), $E$3:E4)) + B5 - D5) -> 7288
A6: 45971 | C6: =IF(B6="", "", SUM($B$4:B6)) | D6: 2548 | E6: =IF(AND(B6="", D6=""), "", N(LOOKUP(2, 1/($E$3:E5<>""), $E$3:E5)) + B6 - D6) -> 4740
A7: 45978 | B7: 3360 | C7: =IF(B7="", "", SUM($B$4:B7)) -> 10648 | E7: =IF(AND(B7="", D7=""), "", N(LOOKUP(2, 1/($E$3:E6<>""), $E$3:E6)) + B7 - D7) -> 8100
A8: 45978 | C8: =IF(B8="", "", SUM($B$4:B8)) | D8: 3360 | E8: =IF(AND(B8="", D8=""), "", N(LOOKUP(2, 1/($E$3:E7<>""), $E$3:E7)) + B8 - D8) -> 4740
A9: 45985 | C9: =IF(B9="", "", SUM($B$4:B9)) | D9: 2000 | E9: =IF(AND(B9="", D9=""), "", N(LOOKUP(2, 1/($E$3:E8<>""), $E$3:E8)) + B9 - D9) -> 2740
A10: 46006 | C10: =IF(B10="", "", SUM($B$4:B10)) | D10: 2000 | E10: =IF(AND(B10="", D10=""), "", N(LOOKUP(2, 1/($E$3:E9<>""), $E$3:E9)) + B10 - D10) -> 740
A11: 46020 | B11: 5282 | C11: =IF(B11="", "", SUM($B$4:B11)) -> 15930 | E11: =IF(AND(B11="", D11=""), "", N(LOOKUP(2, 1/($E$3:E10<>""), $E$3:E10)) + B11 - D11) -> 6022
A12: 46020 | C12: =IF(B12="", "", SUM($B$4:B12)) | D12: 5000 | E12: =IF(AND(B12="", D12=""), "", N(LOOKUP(2, 1/($E$3:E11<>""), $E$3:E11)) + B12 - D12) -> 1022
C13: =IF(B13="", "", SUM($B$4:B13)) | E13: =IF(AND(B13="", D13=""), "", N(LOOKUP(2, 1/($E$3:E12<>""), $E$3:E12)) + B13 - D13)
C14: =IF(B14="", "", SUM($B$4:B14)) | E14: =IF(AND(B14="", D14=""), "", N(LOOKUP(2, 1/($E$3:E13<>""), $E$3:E13)) + B14 - D14)
C15: =IF(B15="", "", SUM($B$4:B15)) | E15: =IF(AND(B15="", D15=""), "", N(LOOKUP(2, 1/($E$3:E14<>""), $E$3:E14)) + B15 - D15)
C16: =IF(B16="", "", SUM($B$4:B16)) | E16: =IF(AND(B16="", D16=""), "", N(LOOKUP(2, 1/($E$3:E15<>""), $E$3:E15)) + B16 - D16)
C17: =IF(B17="", "", SUM($B$4:B17)) | E17: =IF(AND(B17="", D17=""), "", N(LOOKUP(2, 1/($E$3:E16<>""), $E$3:E16)) + B17 - D17)
C18: =IF(B18="", "", SUM($B$4:B18)) | E18: =IF(AND(B18="", D18=""), "", N(LOOKUP(2, 1/($E$3:E17<>""), $E$3:E17)) + B18 - D18)
C19: =IF(B19="", "", SUM($B$4:B19)) | E19: =IF(AND(B19="", D19=""), "", N(LOOKUP(2, 1/($E$3:E18<>""), $E$3:E18)) + B19 - D19)
C20: =IF(B20="", "", SUM($B$4:B20)) | E20: =IF(AND(B20="", D20=""), "", N(LOOKUP(2, 1/($E$3:E19<>""), $E$3:E19)) + B20 - D20)
C21: =IF(B21="", "", SUM($B$4:B21)) | E21: =IF(AND(B21="", D21=""), "", N(LOOKUP(2, 1/($E$3:E20<>""), $E$3:E20)) + B21 - D21)
C22: =IF(B22="", "", SUM($B$4:B22)) | E22: =IF(AND(B22="", D22=""), "", N(LOOKUP(2, 1/($E$3:E21<>""), $E$3:E21)) + B22 - D22)
C23: =IF(B23="", "", SUM($B$4:B23)) | E23: =IF(AND(B23="", D23=""), "", N(LOOKUP(2, 1/($E$3:E22<>""), $E$3:E22)) + B23 - D23)
C24: =IF(B24="", "", SUM($B$4:B24)) | E24: =IF(AND(B24="", D24=""), "", N(LOOKUP(2, 1/($E$3:E23<>""), $E$3:E23)) + B24 - D24)
... C100: =IF(B100="", "", SUM($B$4:B100)) | E100: =IF(AND(B100="", D100=""), "", N(LOOKUP(2, 1/($E$3:E99<>""), $E$3:E99)) + B100 - D100)
C101: =IF(B101="", "", SUM($B$4:B101)) | E101: =IF(AND(B101="", D101=""), "", SUM($B$4:B101) - SUM($D$4:D101))
C102: =IF(B102="", "", SUM($B$4:B102)) | E102: =IF(AND(B102="", D102=""), "", SUM($B$4:B102) - SUM($D$4:D102))

Sheet BhaiBhai
A1: =HYPERLINK("#'Home'!A1", "Home") -> Home | B1: Bhai Bhai Plastic
A3: Date | B3: Product | C3: Total | D3: Deposite | E3: Deu
A4: 45915 | B4: 8450 | C4: =IF(B4="", "", SUM($B$4:B4)) -> 8450 | E4: =IF(AND(B4="", D4=""), "", N(LOOKUP(2, 1/($E$3:E3<>""), $E$3:E3)) + B4 - D4) -> 8450
A5: 45943 | C5: =IF(B5="", "", SUM($B$4:B5)) | D5: 2000 | E5: =IF(AND(B5="", D5=""), "", N(LOOKUP(2, 1/($E$3:E4<>""), $E$3:E4)) + B5 - D5) -> 6450
A6: 46041 | C6: =IF(B6="", "", SUM($B$4:B6)) | D6: 3000 | E6: =IF(AND(B6="", D6=""), "", N(LOOKUP(2, 1/($E$3:E5<>""), $E$3:E5)) + B6 - D6) -> 3450
C7: =IF(B7="", "", SUM($B$4:B7)) | E7: =IF(AND(B7="", D7=""), "", N(LOOKUP(2, 1/($E$3:E6<>""), $E$3:E6)) + B7 - D7)
C8: =IF(B8="", "", SUM($B$4:B8)) | E8: =IF(AND(B8="", D8=""), "", N(LOOKUP(2, 1/($E$3:E7<>""), $E$3:E7)) + B8 - D8)
C9: =IF(B9="", "", SUM($B$4:B9)) | E9: =IF(AND(B9="", D9=""), "", N(LOOKUP(2, 1/($E$3:E8<>""), $E$3:E8)) + B9 - D9)
C10: =IF(B10="", "", SUM($B$4:B10)) | E10: =IF(AND(B10="", D10=""), "", N(LOOKUP(2, 1/($E$3:E9<>""), $E$3:E9)) + B10 - D10)
C11: =IF(B11="", "", SUM($B$4:B11)) | E11: =IF(AND(B11="", D11=""), "", N(LOOKUP(2, 1/($E$3:E10<>""), $E$3:E10)) + B11 - D11)
C12: =IF(B12="", "", SUM($B$4:B12)) | E12: =IF(AND(B12="", D12=""), "", N(LOOKUP(2, 1/($E$3:E11<>""), $E$3:E11)) + B12 - D12)
C13: =IF(B13="", "", SUM($B$4:B13)) | E13: =IF(AND(B13="", D13=""), "", N(LOOKUP(2, 1/($E$3:E12<>""), $E$3:E12)) + B13 - D13)
C14: =IF(B14="", "", SUM($B$4:B14)) | E14: =IF(AND(B14="", D14=""), "", N(LOOKUP(2, 1/($E$3:E13<>""), $E$3:E13)) + B14 - D14)
C15: =IF(B15="", "", SUM($B$4:B15)) | E15: =IF(AND(B15="", D15=""), "", N(LOOKUP(2, 1/($E$3:E14<>""), $E$3:E14)) + B15 - D15)
C16: =IF(B16="", "", SUM($B$4:B16)) | E16: =IF(AND(B16="", D16=""), "", N(LOOKUP(2, 1/($E$3:E15<>""), $E$3:E15)) + B16 - D16)
C17: =IF(B17="", "", SUM($B$4:B17)) | E17: =IF(AND(B17="", D17=""), "", N(LOOKUP(2, 1/($E$3:E16<>""), $E$3:E16)) + B17 - D17)
C18: =IF(B18="", "", SUM($B$4:B18)) | E18: =IF(AND(B18="", D18=""), "", N(LOOKUP(2, 1/($E$3:E17<>""), $E$3:E17)) + B18 - D18)
... C100: =IF(B100="", "", SUM($B$4:B100)) | E100: =IF(AND(B100="", D100=""), "", N(LOOKUP(2, 1/($E$3:E99<>""), $E$3:E99)) + B100 - D100)
C101: =IF(B101="", "", SUM($B$4:B101)) | E101: =IF(AND(B101="", D101=""), "", SUM($B$4:B101) - SUM($D$4:D101))
C102: =IF(B102="", "", SUM($B$4:B102)) | E102: =IF(AND(B102="", D102=""), "", SUM($B$4:B102) - SUM($D$4:D102))

Sheet Akon
A1: =HYPERLINK("#'Home'!A1", "Home") -> Home | B1: Akon Crockery
A3: Date | B3: Product | C3: Total | D3: Deposite | E3: Deu
A4: 45957 | B4: 74778 | C4: =IF(B4="", "", SUM($B$4:B4)) -> 74778 | E4: =IF(AND(B4="", D4=""), "", N(LOOKUP(2, 1/($E$3:E3<>""), $E$3:E3)) + B4 - D4) -> 74778
A5: 45957 | C5: =IF(B5="", "", SUM($B$4:B5)) | D5: 10000 | E5: =IF(AND(B5="", D5=""), "", N(LOOKUP(2, 1/($E$3:E4<>""), $E$3:E4)) + B5 - D5) -> 64778
A6: 45964 | C6: =IF(B6="", "", SUM($B$4:B6)) | D6: 5000 | E6: =IF(AND(B6="", D6=""), "", N(LOOKUP(2, 1/($E$3:E5<>""), $E$3:E5)) + B6 - D6) -> 59778
A7: 45971 | C7: =IF(B7="", "", SUM($B$4:B7)) | D7: 5000 | E7: =IF(AND(B7="", D7=""), "", N(LOOKUP(2, 1/($E$3:E6<>""), $E$3:E6)) + B7 - D7) -> 54778
A8: 45978 | C8: =IF(B8="", "", SUM($B$4:B8)) | D8: 6000 | E8: =IF(AND(B8="", D8=""), "", N(LOOKUP(2, 1/($E$3:E7<>""), $E$3:E7)) + B8 - D8) -> 48778
