Workbook

Sheet Memo
A1: M/S Swarna Enterprise
A2: Bill of: Sales Central-Cookware
A5: Invoice No: | B5: 24865 | D5: Party Code:
D6: Party Name: | E6: Digital Aluminium
A7: Ref No: | B7: D4-05092/26 | D7: Address: | E7: Safa, Mathbaria
A8: Date: | B8: 46216 | D8: Contact: | E8: 1714510583
A9: Gate Pass Ref: | B9: 45863 | D9: NID:
A11: Note: | B11: D4-05092/26 .Van-Shamim
A13: Serial No | B13: Description Of Goods | C13: Quantity | D13: Rate | E13: Amount
A14: 1 | B14: Infrared Cooker CMT-22 | C14: 1 | D14: 3375 | E14: =IF(OR(C14="", D14=""), "", C14*D14) -> 3375
E15: =IF(OR(C15="", D15=""), "", C15*D15)
E16: =IF(OR(C16="", D16=""), "", C16*D16)
E17: =IF(OR(C17="", D17=""), "", C17*D17)
E18: =IF(OR(C18="", D18=""), "", C18*D18)
E19: =IF(OR(C19="", D19=""), "", C19*D19)
A20: 2 | B20: SS Electric Kettle-1.8Ltr (UnDelivery) | C20: 1 | D20: 0 | E20: =IF(OR(C20="", D20=""), "", C20*D20) -> 0
A21: 3 | B21: SS Electric Kettle- Lower Part Black | C21: 1 | D21: 0 | E21: =IF(OR(C21="", D21=""), "", C21*D21) -> 0
E22: =IF(OR(C22="", D22=""), "", C22*D22)
E23: =IF(OR(C23="", D23=""), "", C23*D23)
E24: =IF(OR(C24="", D24=""), "", C24*D24)
E25: =IF(OR(C25="", D25=""), "", C25*D25)
E26: =IF(OR(C26="", D26=""), "", C26*D26)
E27: =IF(OR(C27="", D27=""), "", C27*D27)
E28: =IF(OR(C28="", D28=""), "", C28*D28)
E29: =IF(OR(C29="", D29=""), "", C29*D29)
E30: =IF(OR(C30="", D30=""), "", C30*D30)
E31: =IF(OR(C31="", D31=""), "", C31*D31)
E32: =IF(OR(C32="", D32=""), "", C32*D32)
E33: =IF(OR(C33="", D33=""), "", C33*D33)
... E35: =IF(OR(C35="", D35=""), "", C35*D35)
A36: TOTAL: | B36: =SUM(C14:C35) -> 3 | E36: =SUM(E14:E35) -> 3375
A37: Cash Discount | B37: (-)% | E37: =E36*(D37/E36) -> 0
A38: Commission | B38: (-)% | E38: =(E36-E37)*(D38/100) -> 0
A39: Commission | B39: (-)% | E39: =(E36-E37-E38)*(D39/100) -> 0
A40: Final Total: | B40: =E36-E37-E38-E39 -> 3375
A44: Prepared By:....... | B44: Checked BY:........ | D44: Authorized BY:....... | E44: Customer Signature:.....

Sheet Sheet2
D4: Input | F4: K/Y
D8: Group | E8: Code | F8: Name | G8: Size | H8: DP | I8: D. 12
D9: {=_xlfn._xlws.FILTER(Sheet1!B2:F512, TRIM(Sheet1!B2:B512) = TRIM(F4))} -> K/Y | E9: HE18-08 | F9: Glass Electric Kettle | G9: 1.8 | H9: 1300 | I9: {=IFERROR(IF(E9="", "", INDEX(Sheet1!$G:$J, MATCH(E9, Sheet1!$C:$C, 0), IF(COUNTIF(Sheet1!$G:$G, $I$8)>0, 1, IF(COUNTIF(Sheet1!$H:$H, $I$8)>0, 2, IF(COUNTIF(Sheet1!$I:$I, $I$8)>0, 3, IF(COUNTIF(Sheet1!$J:$J, $I$8)>0, 4, 0)))))), "")} -> 1144
D10: K/Y | E10: HS18-07 | F10: PL Electric Kettle | G10: 1.8 | H10: 950 | I10: {=IFERROR(IF(E10="", "", INDEX(Sheet1!$G:$J, MATCH(E10, Sheet1!$C:$C, 0), IF(COUNTIF(Sheet1!$G:$G, $I$8)>0, 1, IF(COUNTIF(Sheet1!$H:$H, $I$8)>0, 2, IF(COUNTIF(Sheet1!$I:$I, $I$8)>0, 3, IF(COUNTIF(Sheet1!$J:$J, $I$8)>0, 4, 0)))))), "")} -> 836
D11: K/Y | E11: HS18-05 | F11: SS Electric Kettle | G11: 1.8 | H11: 835 | I11: {=IFERROR(IF(E11="", "", INDEX(Sheet1!$G:$J, MATCH(E11, Sheet1!$C:$C, 0), IF(COUNTIF(Sheet1!$G:$G, $I$8)>0, 1, IF(COUNTIF(Sheet1!$H:$H, $I$8)>0, 2, IF(COUNTIF(Sheet1!$I:$I, $I$8)>0, 3, IF(COUNTIF(Sheet1!$J:$J, $I$8)>0, 4, 0)))))), "")} -> 734.8
D12: K/Y | E12: HS18-06 | F12: SS Electric Kettle | G12: 2.2 | H12: 950 | I12: {=IFERROR(IF(E12="", "", INDEX(Sheet1!$G:$J, MATCH(E12, Sheet1!$C:$C, 0), IF(COUNTIF(Sheet1!$G:$G, $I$8)>0, 1, IF(COUNTIF(Sheet1!$H:$H, $I$8)>0, 2, IF(COUNTIF(Sheet1!$I:$I, $I$8)>0, 3, IF(COUNTIF(Sheet1!$J:$J, $I$8)>0, 4, 0)))))), "")} -> 836
I13: {=IFERROR(IF(E13="", "", INDEX(Sheet1!$G:$J, MATCH(E13, Sheet1!$C:$C, 0), IF(COUNTIF(Sheet1!$G:$G, $I$8)>0, 1, IF(COUNTIF(Sheet1!$H:$H, $I$8)>0, 2, IF(COUNTIF(Sheet1!$I:$I, $I$8)>0, 3, IF(COUNTIF(Sheet1!$J:$J, $I$8)>0, 4, 0)))))), "")}
I14: {=IFERROR(IF(E14="", "", INDEX(Sheet1!$G:$J, MATCH(E14, Sheet1!$C:$C, 0), IF(COUNTIF(Sheet1!$G:$G, $I$8)>0, 1, IF(COUNTIF(Sheet1!$H:$H, $I$8)>0, 2, IF(COUNTIF(Sheet1!$I:$I, $I$8)>0, 3, IF(COUNTIF(Sheet1!$J:$J, $I$8)>0, 4, 0)))))), "")}
I15: {=IFERROR(IF(E15="", "", INDEX(Sheet1!$G:$J, MATCH(E15, Sheet1!$C:$C, 0), IF(COUNTIF(Sheet1!$G:$G, $I$8)>0, 1, IF(COUNTIF(Sheet1!$H:$H, $I$8)>0, 2, IF(COUNTIF(Sheet1!$I:$I, $I$8)>0, 3, IF(COUNTIF(Sheet1!$J:$J, $I$8)>0, 4, 0)))))), "")}
I16: {=IFERROR(IF(E16="", "", INDEX(Sheet1!$G:$J, MATCH(E16, Sheet1!$C:$C, 0), IF(COUNTIF(Sheet1!$G:$G, $I$8)>0, 1, IF(COUNTIF(Sheet1!$H:$H, $I$8)>0, 2, IF(COUNTIF(Sheet1!$I:$I, $I$8)>0, 3, IF(COUNTIF(Sheet1!$J:$J, $I$8)>0, 4, 0)))))), "")}
I17: {=IFERROR(IF(E17="", "", INDEX(Sheet1!$G:$J, MATCH(E17, Sheet1!$C:$C, 0), IF(COUNTIF(Sheet1!$G:$G, $I$8)>0, 1, IF(COUNTIF(Sheet1!$H:$H, $I$8)>0, 2, IF(COUNTIF(Sheet1!$I:$I, $I$8)>0, 3, IF(COUNTIF(Sheet1!$J:$J, $I$8)>0, 4, 0)))))), "")}
I18: {=IFERROR(IF(E18="", "", INDEX(Sheet1!$G:$J, MATCH(E18, Sheet1!$C:$C, 0), IF(COUNTIF(Sheet1!$G:$G, $I$8)>0, 1, IF(COUNTIF(Sheet1!$H:$H, $I$8)>0, 2, IF(COUNTIF(Sheet1!$I:$I, $I$8)>0, 3, IF(COUNTIF(Sheet1!$J:$J, $I$8)>0, 4, 0)))))), "")}
I19: {=IFERROR(IF(E19="", "", INDEX(Sheet1!$G:$J, MATCH(E19, Sheet1!$C:$C, 0), IF(COUNTIF(Sheet1!$G:$G, $I$8)>0, 1, IF(COUNTIF(Sheet1!$H:$H, $I$8)>0, 2, IF(COUNTIF(Sheet1!$I:$I, $I$8)>0, 3, IF(COUNTIF(Sheet1!$J:$J, $I$8)>0, 4, 0)))))), "")}
I20: {=IFERROR(IF(E20="", "", INDEX(Sheet1!$G:$J, MATCH(E20, Sheet1!$C:$C, 0), IF(COUNTIF(Sheet1!$G:$G, $I$8)>0, 1, IF(COUNTIF(Sheet1!$H:$H, $I$8)>0, 2, IF(COUNTIF(Sheet1!$I:$I, $I$8)>0, 3, IF(COUNTIF(Sheet1!$J:$J, $I$8)>0, 4, 0)))))), "")}
I21: {=IFERROR(IF(E21="", "", INDEX(Sheet1!$G:$J, MATCH(E21, Sheet1!$C:$C, 0), IF(COUNTIF(Sheet1!$G:$G, $I$8)>0, 1, IF(COUNTIF(Sheet1!$H:$H, $I$8)>0, 2, IF(COUNTIF(Sheet1!$I:$I, $I$8)>0, 3, IF(COUNTIF(Sheet1!$J:$J, $I$8)>0, 4, 0)))))), "")}
I22: {=IFERROR(IF(E22="", "", INDEX(Sheet1!$G:$J, MATCH(E22, Sheet1!$C:$C, 0), IF(COUNTIF(Sheet1!$G:$G, $I$8)>0, 1, IF(COUNTIF(Sheet1!$H:$H, $I$8)>0, 2, IF(COUNTIF(Sheet1!$I:$I, $I$8)>0, 3, IF(COUNTIF(Sheet1!$J:$J, $I$8)>0, 4, 0)))))), "")}
I23: {=IFERROR(IF(E23="", "", INDEX(Sheet1!$G:$J, MATCH(E23, Sheet1!$C:$C, 0), IF(COUNTIF(Sheet1!$G:$G, $I$8)>0, 1, IF(COUNTIF(Sheet1!$H:$H, $I$8)>0, 2, IF(COUNTIF(Sheet1!$I:$I, $I$8)>0, 3, IF(COUNTIF(Sheet1!$J:$J, $I$8)>0, 4, 0)))))), "")}
I24: {=IFERROR(IF(E24="", "", INDEX(Sheet1!$G:$J, MATCH(E24, Sheet1!$C:$C, 0), IF(COUNTIF(Sheet1!$G:$G, $I$8)>0, 1, IF(COUNTIF(Sheet1!$H:$H, $I$8)>0, 2, IF(COUNTIF(Sheet1!$I:$I, $I$8)>0, 3, IF(COUNTIF(Sheet1!$J:$J, $I$8)>0, 4, 0)))))), "")}
... I774: {=IFERROR(IF(E774="", "", INDEX(Sheet1!$G:$J, MATCH(E774, Sheet1!$C:$C, 0), IF(COUNTIF(Sheet1!$G:$G, $I$8)>0, 1, IF(COUNTIF(Sheet1!$H:$H, $I$8)>0, 2, IF(COUNTIF(Sheet1!$I:$I, $I$8)>0, 3, IF(COUNTIF(Sheet1!$J:$J, $I$8)>0, 4, 0)))))), "")}

Sheet Sheet1
A1: SL | B1: Group | C1: Code | D1: Rice Cooker | E1: Size | F1: DP | G1: D. 10 | H1: B. 12 | I1: D. 12 | J1: B. 14
A2: 1 | B2: R/C | C2: HA15-01 | D2: Still R/C- SS+Alu Pot | E2: 1.8 | F2: 2425 | G2: =F2*90% -> 2182.5 | H2: =F2*90%*98% -> 2138.85 | I2: =F2*88% -> 2134 | J2: =F2*88%*98% -> 2091.32
A3: 2 | B3: R/C | C3: HA15-02 | D3: Still R/C- Singel Alu Pot | E3: 1.8 | F3: 2075 | G3: =F3*90% -> 1867.5 | H3: =F3*90%*98% -> 1830.15 | I3: =F3*88% -> 1826 | J3: =F3*88%*98% -> 1789.48
A4: 3 | B4: R/C | C4: HA15-03 | D4: Still R/C- Singel SS Pot | E4: 1.8 | F4: 2075 | G4: =F4*90% -> 1867.5 | H4: =F4*90%*98% -> 1830.15 | I4: =F4*88% -> 1826 | J4: =F4*88%*98% -> 1789.48
A5: 4 | B5: R/C | C5: HA15-04 | D5: Double SS Pot | E5: 1.8 | F5: 2535 | G5: =F5*90% -> 2281.5 | H5: =F5*90%*98% -> 2235.87 | I5: =F5*88% -> 2230.8 | J5: =F5*88%*98% -> 2186.184
A6: 5 | B6: R/C | C6: HA15-05 | D6: F.B Double SS Pot | E6: 1.8 | F6: 2585 | G6: =F6*90% -> 2326.5 | H6: =F6*90%*98% -> 2279.97 | I6: =F6*88% -> 2274.8 | J6: =F6*88%*98% -> 2229.304
A7: 6 | B7: R/C | C7: HA15-07 | D7: F.B R/C- SS+Alu Pot | E7: 1.8 | F7: 2475 | G7: =F7*90% -> 2227.5 | H7: =F7*90%*98% -> 2182.95 | I7: =F7*88% -> 2178 | J7: =F7*88%*98% -> 2134.44
A8: 7 | B8: R/C | C8: HA15-08 | D8: F.B R/C- Singel Alu Pot | E8: 1.8 | F8: 2125 | G8: =F8*90% -> 1912.5 | H8: =F8*90%*98% -> 1874.25 | I8: =F8*88% -> 1870 | J8: =F8*88%*98% -> 1832.6
A9: 8 | B9: R/C | C9: HA15-10 | D9: F.B R/C- Singel SS Pot | E9: 1.8 | F9: 2125 | G9: =F9*90% -> 1912.5 | H9: =F9*90%*98% -> 1874.25 | I9: =F9*88% -> 1870 | J9: =F9*88%*98% -> 1832.6
A10: 9 | B10: R/C | C10: HA15-11 | D10: Still R/C- SS+Alu Pot | E10: 2.8 | F10: 2965 | G10: =F10*90% -> 2668.5 | H10: =F10*90%*98% -> 2615.13 | I10: =F10*88% -> 2609.2 | J10: =F10*88%*98% -> 2557.016
A11: 10 | B11: R/C | C11: HA15-12 | D11: Still R/C- Singel Alu Pot | E11: 2.8 | F11: 2570 | G11: =F11*90% -> 2313 | H11: =F11*90%*98% -> 2266.74 | I11: =F11*88% -> 2261.6 | J11: =F11*88%*98% -> 2216.368
A12: 11 | B12: R/C | C12: HA15-13 | D12: Still R/C- Singel SS Pot | E12: 2.8 | F12: 2570 | G12: =F12*90% -> 2313 | H12: =F12*90%*98% -> 2266.74 | I12: =F12*88% -> 2261.6 | J12: =F12*88%*98% -> 2216.368
A13: 12 | B13: R/C | C13: HA15-15 | D13: Double SS Pot | E13: 2.8 | F13: 3120 | G13: =F13*90% -> 2808 | H13: =F13*90%*98% -> 2751.84 | I13: =F13*88% -> 2745.6 | J13: =F13*88%*98% -> 2690.688
... A18: 17 | B18: R/C | C18: HR14-11 | D18: J.B R/C- SS+Alu Pot MC R+G Line | E18: 2.8 | F18: 3020 | G18: =F18*90% -> 2718 | H18: =F18*90%*98% -> 2663.64 | I18: =F18*88% -> 2657.6 | J18: =F18*88%*98% -> 2604.448
A21: SL | B21: Group | C21: Code | D21: Pressure Cooker | E21: Size | F21: DP | G21: D. 10 | H21: B. 12 | I21: D. 12 | J21: B. 14
A22: 1 | B22: P/C | C22: HA5-01 | D22: Pressure Cooker Straight | E22: 3.5 | F22: 1255 | G22: =F22*90% -> 1129.5 | H22: =F22*90%*98% -> 1106.91 | I22: =F22*88% -> 1104.4 | J22: =F22*88%*98% -> 1082.312
A23: 2 | B23: P/C | C23: HA5-02 | D23: Pressure Cooker Straight | E23: 4.5 | F23: 1530 | G23: =F23*90% -> 1377 | H23: =F23*90%*98% -> 1349.46 | I23: =F23*88% -> 1346.4 | J23: =F23*88%*98% -> 1319.472
A24: 3 | B24: P/C | C24: HA5-03 | D24: Pressure Cooker Straight | E24: 5.5 | F24: 1605 | G24: =F24*90% -> 1444.5 | H24: =F24*90%*98% -> 1415.61 | I24: =F24*88% -> 1412.4 | J24: =F24*88%*98% -> 1384.152
A25: 4 | B25: P/C | C25: HA5-04 | D25: Pressure Cooker Straight | E25: 6.5 | F25: 1730 | G25: =F25*90% -> 1557 | H25: =F25*90%*98% -> 1525.86 | I25: =F25*88% -> 1522.4 | J25: =F25*88%*98% -> 1491.952
A26: 5 | B26: P/C | C26: HA5-11 | D26: Pressure Cooker Straight | E26: 8 | F26: 2480 | G26: =F26*90% -> 2232 | H26: =F26*90%*98% -> 2187.36 | I26: =F26*88% -> 2182.4 | J26: =F26*88%*98% -> 2138.752
A27: 6 | B27: P/C | C27: HA5-05 | D27: Pressure Cooker Straight IB | E27: 3.5 | F27: 1330 | G27: =F27*90% -> 1197 | H27: =F27*90%*98% -> 1173.06 | I27: =F27*88% -> 1170.4 | J27: =F27*88%*98% -> 1146.992
A28: 7 | B28: P/C | C28: HA5-06 | D28: Pressure Cooker Straight IB | E28: 4.5 | F28: 1605 | G28: =F28*90% -> 1444.5 | H28: =F28*90%*98% -> 1415.61 | I28: =F28*88% -> 1412.4 | J28: =F28*88%*98% -> 1384.152
A29: 8 | B29: P/C | C29: HA5-07 | D29: Pressure Cooker Straight IB | E29: 5.5 | F29: 1680 | G29: =F29*90% -> 1512 | H29: =F29*90%*98% -> 1481.76 | I29: =F29*88% -> 1478.4 | J29: =F29*88%*98% -> 1448.832
A30: 9 | B30: P/C | C30: HA5-08 | D30: Pressure Cooker Straight IB | E30: 6.5 | F30: 1805 | G30: =F30*90% -> 1624.5 | H30: =F30*90%*98% -> 1592.01 | I30: =F30*88% -> 1588.4 | J30: =F30*88%*98% -> 1556.632
A31: 10 | B31: P/C | C31: HA5-12 | D31: Pressure Cooker Straight IB | E31: 8 | F31: 2555 | G31: =F31*90% -> 2299.5 | H31: =F31*90%*98% -> 2253.51 | I31: =F31*88% -> 2248.4 | J31: =F31*88%*98% -> 2203.432
A32: 11 | B32: P/C | C32: HA5-09 | D32: Pressure Cooker Straight | E32: 2.5 | F32: 1155 | G32: =F32*90% -> 1039.5 | H32: =F32*90%*98% -> 1018.71 | I32: =F32*88% -> 1016.4 | J32: =F32*88%*98% -> 996.072
A33: 12 | B33: P/C | C33: HA5-10 | D33: Pressure Cooker Straight IB | E33: 2.5 | F33: 1230 | G33: =F33*90% -> 1107 | H33: =F33*90%*98% -> 1084.86 | I33: =F33*88% -> 1082.4 | J33: =F33*88%*98% -> 1060.752
... A39: 18 | B39: P/C | C39: HA6-06 | D39: Pressure Cooker Oval IB | E39: 5.5 | F39: 1760 | G39: =F39*90% -> 1584 | H39: =F39*90%*98% -> 1552.32 | I39: =F39*88% -> 1548.8 | J39: =F39*88%*98% -> 1517.824
A40: 19 | B40: P/C | C40: HS21-01 | D40: SS 3 Layer Pressure Cooker | E40: 3.5 | F40: 1840 | G40: =F40*94% -> 1729.6 | H40: =F40*94%*98% -> 1695.008
A41: 20 | B41: P/C | C41: HS21-02 | D41: SS 3 Layer Pressure Cooker | E41: 4.5 | F41: 2050 | G41: =F41*94% -> 1927 | H41: =F41*94%*98% -> 1888.46
A42: 21 | B42: P/C | C42: HS21-03 | D42: SS 3 Layer Pressure Cooker | E42: 5.5 | F42: 2365 | G42: =F42*94% -> 2223.1 | H42: =F42*94%*98% -> 2178.638
A43: 22 | B43: P/C | C43: HS21-04 | D43: SS 3 Layer Pressure Cooker | E43: 6.5 | F43: 2575 | G43: =F43*94% -> 2420.5 | H43: =F43*94%*98% -> 2372.09
A48: SL | B48: Group | C48: Code | D48: Casserole | E48: Size | F48: DP | G48: D. 10 | H48: B. 12 | I48: D. 12 | J48: B. 14
A49: 1 | B49: C/P | C49: HAF1-01 | D49: Casserole Pan | E49: 18 | F49: 975 | G49: =F49*90% -> 877.5 | H49: =F49*90%*98% -> 859.95 | I49: =F49*88% -> 858 | J49: =F49*88%*98% -> 840.84
A50: 2 | B50: C/P | C50: HAF1-02 | D50: Casserole Pan | E50: 20 | F50: 1105 | G50: =F50*90% -> 994.5 | H50: =F50*90%*98% -> 974.61 | I50: =F50*88% -> 972.4 | J50: =F50*88%*98% -> 952.952
A51: 3 | B51: C/P | C51: HAF1-03 | D51: Casserole Pan | E51: 22 | F51: 1240 | G51: =F51*90% -> 1116 | H51: =F51*90%*98% -> 1093.68 | I51: =F51*88% -> 1091.2 | J51: =F51*88%*98% -> 1069.376
A52: 4 | B52: C/P | C52: HAF1-04 | D52: Casserole Pan | E52: 24 | F52: 1435 | G52: =F52*90% -> 1291.5 | H52: =F52*90%*98% -> 1265.67 | I52: =F52*88% -> 1262.8 | J52: =F52*88%*98% -> 1237.544
A53: 5 | B53: C/P | C53: HAF1-05 | D53: Casserole Pan | E53: 26 | F53: 1570 | G53: =F53*90% -> 1413 | H53: =F53*90%*98% -> 1384.74 | I53: =F53*88% -> 1381.6 | J53: =F53*88%*98% -> 1353.968
A54: 6 | B54: C/P | C54: HAF1-06 | D54: Casserole Pan | E54: 28 | F54: 1820 | G54: =F54*90% -> 1638 | H54: =F54*90%*98% -> 1605.24 | I54: =F54*88% -> 1601.6 | J54: =F54*88%*98% -> 1569.568
A55: 7 | B55: C/P | C55: HAF1-07 | D55: Casserole Pan IB | E55: 18 | F55: 1050 | G55: =F55*90% -> 945 | H55: =F55*90%*98% -> 926.1 | I55: =F55*88% -> 924 | J55: =F55*88%*98% -> 905.52
...

Sheet Sheet4

Sheet Sheet3
C2: Group | E2: =Sheet1!G1 -> D. 10
C3: R/C | E3: B. 12
C4: P/C | E4: =Sheet1!I1 -> D. 12
C5: C/P | E5: =Sheet1!J1 -> B. 14
C6: F/P | E6: =Sheet1!G120 -> D. 6
C7: SS/F/P | E7: =Sheet1!H120 -> B. 8
C8: Gift
C9: W/P
C10: M/P
C11: R/T
C12: P/P
C13: S/P
C14: TH/P
C15: Plate
C16: Bowl
C17: K/Y
C18: I/C
C19: B/L
C20: G/S
